Workbook

Sheet DASHBOARD
B2: DASHBOARD ANUAL - FREEWILL STUDIO 2026
B3: Control Financiero y Análisis de Rendimiento de Tatuajes y Piercings
B5: INGRESOS TOTALES | E5: GANANCIA ESTUDIO (NETO) | H5: COMISIONES ARTISTAS
B6: =E23 -> 283720 | E6: =H23 -> 139330 | H6: =G23 -> 144390
B9: RESUMEN VENTAS MENSUALES
B10: MES | C10: TATTOOS | D10: PIERCINGS | E10: VENTAS TOTALES | F10: PROPINAS | G10: COMISIÓN ARTISTAS | H10: NETO ESTUDIO
B11: ENERO | C11: =SUMIFS(ENERO!E:E, ENERO!C:C, "TATTOO", ENERO!B:B, "<>TOTAL") -> 61400 | D11: =SUMIFS(ENERO!E:E, ENERO!C:C, "PIERCING", ENERO!B:B, "<>TOTAL") -> 900 | E11: =SUMIFS(ENERO!E:E, ENERO!B:B, "<>TOTAL") -> 62300 | F11: =SUMIFS(ENERO!F:F, ENERO!B:B, "<>TOTAL") -> 300 | G11: =SUMIFS(ENERO!J:J, ENERO!B:B, "<>TOTAL") -> 32350 | H11: =SUMIFS(ENERO!K:K, ENERO!B:B, "<>TOTAL") -> 29950
B12: FEBRERO | C12: =SUMIFS(FEBRERO!E:E, FEBRERO!C:C, "TATTOO", FEBRERO!B:B, "<>TOTAL") -> 50600 | D12: =SUMIFS(FEBRERO!E:E, FEBRERO!C:C, "PIERCING", FEBRERO!B:B, "<>TOTAL") -> 2550 | E12: =SUMIFS(FEBRERO!E:E, FEBRERO!B:B, "<>TOTAL") -> 53150 | F12: =SUMIFS(FEBRERO!F:F, FEBRERO!B:B, "<>TOTAL") -> 300 | G12: =SUMIFS(FEBRERO!J:J, FEBRERO!B:B, "<>TOTAL") -> 26995 | H12: =SUMIFS(FEBRERO!K:K, FEBRERO!B:B, "<>TOTAL") -> 26155
B13: MARZO | C13: =SUMIFS(MARZO!E:E, MARZO!C:C, "TATTOO", MARZO!B:B, "<>TOTAL") -> 16750 | D13: =SUMIFS(MARZO!E:E, MARZO!C:C, "PIERCING", MARZO!B:B, "<>TOTAL") -> 0 | E13: =SUMIFS(MARZO!E:E, MARZO!B:B, "<>TOTAL") -> 16750 | F13: =SUMIFS(MARZO!F:F, MARZO!B:B, "<>TOTAL") -> 0 | G13: =SUMIFS(MARZO!J:J, MARZO!B:B, "<>TOTAL") -> 9285 | H13: =SUMIFS(MARZO!K:K, MARZO!B:B, "<>TOTAL") -> 7465
B14: ABRIL | C14: =SUMIFS(ABRIL!E:E, ABRIL!C:C, "TATTOO", ABRIL!B:B, "<>TOTAL") -> 39400 | D14: =SUMIFS(ABRIL!E:E, ABRIL!C:C, "PIERCING", ABRIL!B:B, "<>TOTAL") -> 2100 | E14: =SUMIFS(ABRIL!E:E, ABRIL!B:B, "<>TOTAL") -> 41500 | F14: =SUMIFS(ABRIL!F:F, ABRIL!B:B, "<>TOTAL") -> 0 | G14: =SUMIFS(ABRIL!J:J, ABRIL!B:B, "<>TOTAL") -> 20750 | H14: =SUMIFS(ABRIL!K:K, ABRIL!B:B, "<>TOTAL") -> 20750
B15: MAYO | C15: =SUMIFS(MAYO!E:E, MAYO!C:C, "TATTOO", MAYO!B:B, "<>TOTAL") -> 26600 | D15: =SUMIFS(MAYO!E:E, MAYO!C:C, "PIERCING", MAYO!B:B, "<>TOTAL") -> 700 | E15: =SUMIFS(MAYO!E:E, MAYO!B:B, "<>TOTAL") -> 27300 | F15: =SUMIFS(MAYO!F:F, MAYO!B:B, "<>TOTAL") -> 1000 | G15: =SUMIFS(MAYO!J:J, MAYO!B:B, "<>TOTAL") -> 13650 | H15: =SUMIFS(MAYO!K:K, MAYO!B:B, "<>TOTAL") -> 13650
B16: JUNIO | C16: =SUMIFS(JUNIO!E:E, JUNIO!C:C, "TATTOO", JUNIO!B:B, "<>TOTAL") -> 43250 | D16: =SUMIFS(JUNIO!E:E, JUNIO!C:C, "PIERCING", JUNIO!B:B, "<>TOTAL") -> 0 | E16: =SUMIFS(JUNIO!E:E, JUNIO!B:B, "<>TOTAL") -> 43250 | F16: =SUMIFS(JUNIO!F:F, JUNIO!B:B, "<>TOTAL") -> 0 | G16: =SUMIFS(JUNIO!J:J, JUNIO!B:B, "<>TOTAL") -> 21625 | H16: =SUMIFS(JUNIO!K:K, JUNIO!B:B, "<>TOTAL") -> 21625
B17: JULIO | C17: =SUMIFS(JULIO!E:E, JULIO!C:C, "TATTOO", JULIO!B:B, "<>TOTAL") -> 38970 | D17: =SUMIFS(JULIO!E:E, JULIO!C:C, "PIERCING", JULIO!B:B, "<>TOTAL") -> 500 | E17: =SUMIFS(JULIO!E:E, JULIO!B:B, "<>TOTAL") -> 39470 | F17: =SUMIFS(JULIO!F:F, JULIO!B:B, "<>TOTAL") -> 0 | G17: =SUMIFS(JULIO!J:J, JULIO!B:B, "<>TOTAL") -> 19735 | H17: =SUMIFS(JULIO!K:K, JULIO!B:B, "<>TOTAL") -> 19735
B18: AGOSTO | C18: =SUMIFS(AGOSTO!E:E, AGOSTO!C:C, "TATTOO", AGOSTO!B:B, "<>TOTAL") -> 0 | D18: =SUMIFS(AGOSTO!E:E, AGOSTO!C:C, "PIERCING", AGOSTO!B:B, "<>TOTAL") -> 0 | E18: =SUMIFS(AGOSTO!E:E, AGOSTO!B:B, "<>TOTAL") -> 0 | F18: =SUMIFS(AGOSTO!F:F, AGOSTO!B:B, "<>TOTAL") -> 0 | G18: =SUMIFS(AGOSTO!J:J, AGOSTO!B:B, "<>TOTAL") -> 0 | H18: =SUMIFS(AGOSTO!K:K, AGOSTO!B:B, "<>TOTAL") -> 0
B19: SEPTIEMBRE | C19: =SUMIFS(SEPTIEMBRE!E:E, SEPTIEMBRE!C:C, "TATTOO", SEPTIEMBRE!B:B, "<>TOTAL") -> 0 | D19: =SUMIFS(SEPTIEMBRE!E:E, SEPTIEMBRE!C:C, "PIERCING", SEPTIEMBRE!B:B, "<>TOTAL") -> 0 | E19: =SUMIFS(SEPTIEMBRE!E:E, SEPTIEMBRE!B:B, "<>TOTAL") -> 0 | F19: =SUMIFS(SEPTIEMBRE!F:F, SEPTIEMBRE!B:B, "<>TOTAL") -> 0 | G19: =SUMIFS(SEPTIEMBRE!J:J, SEPTIEMBRE!B:B, "<>TOTAL") -> 0 | H19: =SUMIFS(SEPTIEMBRE!K:K, SEPTIEMBRE!B:B, "<>TOTAL") -> 0
B20: OCTUBRE | C20: =SUMIFS(OCTUBRE!E:E, OCTUBRE!C:C, "TATTOO", OCTUBRE!B:B, "<>TOTAL") -> 0 | D20: =SUMIFS(OCTUBRE!E:E, OCTUBRE!C:C, "PIERCING", OCTUBRE!B:B, "<>TOTAL") -> 0 | E20: =SUMIFS(OCTUBRE!E:E, OCTUBRE!B:B, "<>TOTAL") -> 0 | F20: =SUMIFS(OCTUBRE!F:F, OCTUBRE!B:B, "<>TOTAL") -> 0 | G20: =SUMIFS(OCTUBRE!J:J, OCTUBRE!B:B, "<>TOTAL") -> 0 | H20: =SUMIFS(OCTUBRE!K:K, OCTUBRE!B:B, "<>TOTAL") -> 0
B21: NOVIEMBRE | C21: =SUMIFS(NOVIEMBRE!E:E, NOVIEMBRE!C:C, "TATTOO", NOVIEMBRE!B:B, "<>TOTAL") -> 0 | D21: =SUMIFS(NOVIEMBRE!E:E, NOVIEMBRE!C:C, "PIERCING", NOVIEMBRE!B:B, "<>TOTAL") -> 0 | E21: =SUMIFS(NOVIEMBRE!E:E, NOVIEMBRE!B:B, "<>TOTAL") -> 0 | F21: =SUMIFS(NOVIEMBRE!F:F, NOVIEMBRE!B:B, "<>TOTAL") -> 0 | G21: =SUMIFS(NOVIEMBRE!J:J, NOVIEMBRE!B:B, "<>TOTAL") -> 0 | H21: =SUMIFS(NOVIEMBRE!K:K, NOVIEMBRE!B:B, "<>TOTAL") -> 0
B22: DICIEMBRE | C22: =SUMIFS(DICIEMBRE!E:E, DICIEMBRE!C:C, "TATTOO", DICIEMBRE!B:B, "<>TOTAL") -> 0 | D22: =SUMIFS(DICIEMBRE!E:E, DICIEMBRE!C:C, "PIERCING", DICIEMBRE!B:B, "<>TOTAL") -> 0 | E22: =SUMIFS(DICIEMBRE!E:E, DICIEMBRE!B:B, "<>TOTAL") -> 0 | F22: =SUMIFS(DICIEMBRE!F:F, DICIEMBRE!B:B, "<>TOTAL") -> 0 | G22: =SUMIFS(DICIEMBRE!J:J, DICIEMBRE!B:B, "<>TOTAL") -> 0 | H22: =SUMIFS(DICIEMBRE!K:K, DICIEMBRE!B:B, "<>TOTAL") -> 0
B23: TOTAL ANUAL | C23: =SUM(C11:C22) -> 276970 | D23: =SUM(D11:D22) -> 6750 | E23: =SUM(E11:E22) -> 283720 | F23: =SUM(F11:F22) -> 1600 | G23: =SUM(G11:G22) -> 144390 | H23: =SUM(H11:H22) -> 139330
B25: RENDIMIENTO POR ARTISTA | G25: VENTAS POR TIPO DE SERVICIO
B26: ARTISTA | C26: TRABAJOS REALIZADOS | D26: VENTAS TOTALES | E26: COMISIONES PAGADAS | G26: TIPO SERVICIO | H26: CANTIDAD | I26: VENTAS TOTALES
B27: VONY | C27: =COUNTIFS(ENERO!D:D, B27, ENERO!B:B, "<>TOTAL") + COUNTIFS(FEBRERO!D:D, B27, FEBRERO!B:B, "<>TOTAL") + COUNTIFS(MARZO!D:D, B27, MARZO!B:B, "<>TOTAL") + COUNTIFS(ABRIL!D:D, B27, ABRIL!B:B, "<>TOTAL") + COUNTIFS(MAYO!D:D, B27, MAYO!B:B, "<>TOTAL") + COUNTIFS(JUNIO!D:D, B27, JUNIO!B:B, "<>TOTAL") + COUNTIFS(JULIO!D:D, B27, JULIO!B:B, "<>TOTAL") + COUNTIFS(AGOSTO!D:D, B27, AGOSTO!B:B, "<>TOTAL") + COUNTIFS(SEPTIEMBRE!D:D, B27, SEPTIEMBRE!B:B, "<>TOTAL") + COUNTIFS(OCTUBRE!D:D, B27, OCTUBRE!B:B, "<>TOTAL") + COUNTIFS(NOVIEMBRE!D:D, B27, NOVIEMBRE!B:B, "<>TOTAL") + COUNTIFS(DICIEMBRE!D:D, B27, DICIEMBRE!B:B, "<>TOTAL") -> 95 | D27: =SUMIFS(ENERO!E:E, ENERO!D:D, B27, ENERO!B:B, "<>TOTAL") + SUMIFS(FEBRERO!E:E, FEBRERO!D:D, B27, FEBRERO!B:B, "<>TOTAL") + SUMIFS(MARZO!E:E, MARZO!D:D, B27, MARZO!B:B, "<>TOTAL") + SUMIFS(ABRIL!E:E, ABRIL!D:D, B27, ABRIL!B:B, "<>TOTAL") + SUMIFS(MAYO!E:E, MAYO!D:D, B27, MAYO!B:B, "<>TOTAL") + SUMIFS(JUNIO!E:E, JUNIO!D:D, B27, JUNIO!B:B, "<>TOTAL") + SUMIFS(JULIO!E:E, JULIO!D:D, B27, JULIO!B:B, "<>TOTAL") + SUMIFS(AGOSTO!E:E, AGOSTO!D:D, B27, AGOSTO!B:B, "<>TOTAL") + SUMIFS(SEPTIEMBRE!E:E, SEPTIEMBRE!D:D, B27, SEPTIEMBRE!B:B, "<>TOTAL") + SUMIFS(OCTUBRE!E:E, OCTUBRE!D:D, B27, OCTUBRE!B:B, "<>TOTAL") + SUMIFS(NOVIEMBRE!E:E, NOVIEMBRE!D:D, B27, NOVIEMBRE!B:B, "<>TOTAL") + SUMIFS(DICIEMBRE!E:E, DICIEMBRE!D:D, B27, DICIEMBRE!B:B, "<>TOTAL") -> 254070 | E27: =SUMIFS(ENERO!J:J, ENERO!D:D, B27, ENERO!B:B, "<>TOTAL") + SUMIFS(FEBRERO!J:J, FEBRERO!D:D, B27, FEBRERO!B:B, "<>TOTAL") + SUMIFS(MARZO!J:J, MARZO!D:D, B27, MARZO!B:B, "<>TOTAL") + SUMIFS(ABRIL!J:J, ABRIL!D:D, B27, ABRIL!B:B, "<>TOTAL") + SUMIFS(MAYO!J:J, MAYO!D:D, B27, MAYO!B:B, "<>TOTAL") + SUMIFS(JUNIO!J:J, JUNIO!D:D, B27, JUNIO!B:B, "<>TOTAL") + SUMIFS(JULIO!J:J, JULIO!D:D, B27, JULIO!B:B, "<>TOTAL") + SUMIFS(AGOSTO!J:J, AGOSTO!D:D, B27, AGOSTO!B:B, "<>TOTAL") + SUMIFS(SEPTIEMBRE!J:J, SEPTIEMBRE!D:D, B27, SEPTIEMBRE!B:B, "<>TOTAL") + SUMIFS(OCTUBRE!J:J, OCTUBRE!D:D, B27, OCTUBRE!B:B, "<>TOTAL") + SUMIFS(NOVIEMBRE!J:J, NOVIEMBRE!D:D, B27, NOVIEMBRE!B:B, "<>TOTAL") + SUMIFS(DICIEMBRE!J:J, DICIEMBRE!D:D, B27, DICIEMBRE!B:B, "<>TOTAL") -> 127035 | G27: TATTOO | H27: =COUNTIFS(ENERO!C:C, G27, ENERO!B:B, "<>TOTAL") + COUNTIFS(FEBRERO!C:C, G27, FEBRERO!B:B, "<>TOTAL") + COUNTIFS(MARZO!C:C, G27, MARZO!B:B, "<>TOTAL") + COUNTIFS(ABRIL!C:C, G27, ABRIL!B:B, "<>TOTAL") + COUNTIFS(MAYO!C:C, G27, MAYO!B:B, "<>TOTAL") + COUNTIFS(JUNIO!C:C, G27, JUNIO!B:B, "<>TOTAL") + COUNTIFS(JULIO!C:C, G27, JULIO!B:B, "<>TOTAL") + COUNTIFS(AGOSTO!C:C, G27, AGOSTO!B:B, "<>TOTAL") + COUNTIFS(SEPTIEMBRE!C:C, G27, SEPTIEMBRE!B:B, "<>TOTAL") + COUNTIFS(OCTUBRE!C:C, G27, OCTUBRE!B:B, "<>TOTAL") + COUNTIFS(NOVIEMBRE!C:C, G27, NOVIEMBRE!B:B, "<>TOTAL") + COUNTIFS(DICIEMBRE!C:C, G27, DICIEMBRE!B:B, "<>TOTAL") -> 92 | I27: =SUMIFS(ENERO!E:E, ENERO!C:C, G27, ENERO!B:B, "<>TOTAL") + SUMIFS(FEBRERO!E:E, FEBRERO!C:C, G27, FEBRERO!B:B, "<>TOTAL") + SUMIFS(MARZO!E:E, MARZO!C:C, G27, MARZO!B:B, "<>TOTAL") + SUMIFS(ABRIL!E:E, ABRIL!C:C, G27, ABRIL!B:B, "<>TOTAL") + SUMIFS(MAYO!E:E, MAYO!C:C, G27, MAYO!B:B, "<>TOTAL") + SUMIFS(JUNIO!E:E, JUNIO!C:C, G27, JUNIO!B:B, "<>TOTAL") + SUMIFS(JULIO!E:E, JULIO!C:C, G27, JULIO!B:B, "<>TOTAL") + SUMIFS(AGOSTO!E:E, AGOSTO!C:C, G27, AGOSTO!B:B, "<>TOTAL") + SUMIFS(SEPTIEMBRE!E:E, SEPTIEMBRE!C:C, G27, SEPTIEMBRE!B:B, "<>TOTAL") + SUMIFS(OCTUBRE!E:E, OCTUBRE!C:C, G27, OCTUBRE!B:B, "<>TOTAL") + SUMIFS(NOVIEMBRE!E:E, NOVIEMBRE!C:C, G27, NOVIEMBRE!B:B, "<>TOTAL") + SUMIFS(DICIEMBRE!E:E, DICIEMBRE!C:C, G27, DICIEMBRE!B:B, "<>TOTAL") -> 276970
B28: DAVID | C28: =COUNTIFS(ENERO!D:D, B28, ENERO!B:B, "<>TOTAL") + COUNTIFS(FEBRERO!D:D, B28, FEBRERO!B:B, "<>TOTAL") + COUNTIFS(MARZO!D:D, B28, MARZO!B:B, "<>TOTAL") + COUNTIFS(ABRIL!D:D, B28, ABRIL!B:B, "<>TOTAL") + COUNTIFS(MAYO!D:D, B28, MAYO!B:B, "<>TOTAL") + COUNTIFS(JUNIO!D:D, B28, JUNIO!B:B, "<>TOTAL") + COUNTIFS(JULIO!D:D, B28, JULIO!B:B, "<>TOTAL") + COUNTIFS(AGOSTO!D:D, B28, AGOSTO!B:B, "<>TOTAL") + COUNTIFS(SEPTIEMBRE!D:D, B28, SEPTIEMBRE!B:B, "<>TOTAL") + COUNTIFS(OCTUBRE!D:D, B28, OCTUBRE!B:B, "<>TOTAL") + COUNTIFS(NOVIEMBRE!D:D, B28, NOVIEMBRE!B:B, "<>TOTAL") + COUNTIFS(DICIEMBRE!D:D, B28, DICIEMBRE!B:B, "<>TOTAL") -> 10 | D28: =SUMIFS(ENERO!E:E, ENERO!D:D, B28, ENERO!B:B, "<>TOTAL") + SUMIFS(FEBRERO!E:E, FEBRERO!D:D, B28, FEBRERO!B:B, "<>TOTAL") + SUMIFS(MARZO!E:E, MARZO!D:D, B28, MARZO!B:B, "<>TOTAL") + SUMIFS(ABRIL!E:E, ABRIL!D:D, B28, ABRIL!B:B, "<>TOTAL") + SUMIFS(MAYO!E:E, MAYO!D:D, B28, MAYO!B:B, "<>TOTAL") + SUMIFS(JUNIO!E:E, JUNIO!D:D, B28, JUNIO!B:B, "<>TOTAL") + SUMIFS(JULIO!E:E, JULIO!D:D, B28, JULIO!B:B, "<>TOTAL") + SUMIFS(AGOSTO!E:E, AGOSTO!D:D, B28, AGOSTO!B:B, "<>TOTAL") + SUMIFS(SEPTIEMBRE!E:E, SEPTIEMBRE!D:D, B28, SEPTIEMBRE!B:B, "<>TOTAL") + SUMIFS(OCTUBRE!E:E, OCTUBRE!D:D, B28, OCTUBRE!B:B, "<>TOTAL") + SUMIFS(NOVIEMBRE!E:E, NOVIEMBRE!D:D, B28, NOVIEMBRE!B:B, "<>TOTAL") + SUMIFS(DICIEMBRE!E:E, DICIEMBRE!D:D, B28, DICIEMBRE!B:B, "<>TOTAL") -> 29650 | E28: =SUMIFS(ENERO!J:J, ENERO!D:D, B28, ENERO!B:B, "<>TOTAL") + SUMIFS(FEBRERO!J:J, FEBRERO!D:D, B28, FEBRERO!B:B, "<>TOTAL") + SUMIFS(MARZO!J:J, MARZO!D:D, B28, MARZO!B:B, "<>TOTAL") + SUMIFS(ABRIL!J:J, ABRIL!D:D, B28, ABRIL!B:B, "<>TOTAL") + SUMIFS(MAYO!J:J, MAYO!D:D, B28, MAYO!B:B, "<>TOTAL") + SUMIFS(JUNIO!J:J, JUNIO!D:D, B28, JUNIO!B:B, "<>TOTAL") + SUMIFS(JULIO!J:J, JULIO!D:D, B28, JULIO!B:B, "<>TOTAL") + SUMIFS(AGOSTO!J:J, AGOSTO!D:D, B28, AGOSTO!B:B, "<>TOTAL") + SUMIFS(SEPTIEMBRE!J:J, SEPTIEMBRE!D:D, B28, SEPTIEMBRE!B:B, "<>TOTAL") + SUMIFS(OCTUBRE!J:J, OCTUBRE!D:D, B28, OCTUBRE!B:B, "<>TOTAL") + SUMIFS(NOVIEMBRE!J:J, NOVIEMBRE!D:D, B28, NOVIEMBRE!B:B, "<>TOTAL") + SUMIFS(DICIEMBRE!J:J, DICIEMBRE!D:D, B28, DICIEMBRE!B:B, "<>TOTAL") -> 17355 | G28: PIERCING | H28: =COUNTIFS(ENERO!C:C, G28, ENERO!B:B, "<>TOTAL") + COUNTIFS(FEBRERO!C:C, G28, FEBRERO!B:B, "<>TOTAL") + COUNTIFS(MARZO!C:C, G28, MARZO!B:B, "<>TOTAL") + COUNTIFS(ABRIL!C:C, G28, ABRIL!B:B, "<>TOTAL") + COUNTIFS(MAYO!C:C, G28, MAYO!B:B, "<>TOTAL") + COUNTIFS(JUNIO!C:C, G28, JUNIO!B:B, "<>TOTAL") + COUNTIFS(JULIO!C:C, G28, JULIO!B:B, "<>TOTAL") + COUNTIFS(AGOSTO!C:C, G28, AGOSTO!B:B, "<>TOTAL") + COUNTIFS(SEPTIEMBRE!C:C, G28, SEPTIEMBRE!B:B, "<>TOTAL") + COUNTIFS(OCTUBRE!C:C, G28, OCTUBRE!B:B, "<>TOTAL") + COUNTIFS(NOVIEMBRE!C:C, G28, NOVIEMBRE!B:B, "<>TOTAL") + COUNTIFS(DICIEMBRE!C:C, G28, DICIEMBRE!B:B, "<>TOTAL") -> 13 | I28: =SUMIFS(ENERO!E:E, ENERO!C:C, G28, ENERO!B:B, "<>TOTAL") + SUMIFS(FEBRERO!E:E, FEBRERO!C:C, G28, FEBRERO!B:B, "<>TOTAL") + SUMIFS(MARZO!E:E, MARZO!C:C, G28, MARZO!B:B, "<>TOTAL") + SUMIFS(ABRIL!E:E, ABRIL!C:C, G28, ABRIL!B:B, "<>TOTAL") + SUMIFS(MAYO!E:E, MAYO!C:C, G28, MAYO!B:B, "<>TOTAL") + SUMIFS(JUNIO!E:E, JUNIO!C:C, G28, JUNIO!B:B, "<>TOTAL") + SUMIFS(JULIO!E:E, JULIO!C:C, G28, JULIO!B:B, "<>TOTAL") + SUMIFS(AGOSTO!E:E, AGOSTO!C:C, G28, AGOSTO!B:B, "<>TOTAL") + SUMIFS(SEPTIEMBRE!E:E, SEPTIEMBRE!C:C, G28, SEPTIEMBRE!B:B, "<>TOTAL") + SUMIFS(OCTUBRE!E:E, OCTUBRE!C:C, G28, OCTUBRE!B:B, "<>TOTAL") + SUMIFS(NOVIEMBRE!E:E, NOVIEMBRE!C:C, G28, NOVIEMBRE!B:B, "<>TOTAL") + SUMIFS(DICIEMBRE!E:E, DICIEMBRE!C:C, G28, DICIEMBRE!B:B, "<>TOTAL") -> 6750
B29: TOTAL | C29: =SUM(C27:C28) -> 105 | D29: =SUM(D27:D28) -> 283720 | E29: =SUM(E27:E28) -> 144390 | G29: TOTAL | H29: =SUM(H27:H28) -> 105 | I29: =SUM(I27:I28) -> 283720

Sheet CLIENTES
B2: BASE DE DATOS Y FRECUENCIA DE CLIENTES
B3: Análisis acumulado de visitas y fidelidad de clientes
B5: ID CLIENTE | C5: NOMBRE CLIENTE | D5: CONTACTO | E5: TOTAL VISITAS | F5: GASTO TOTAL | G5: ESTADO CLIENTE
B6: CLI-001 | C6: Emmanuel | D6: 9842712892 | E6: =COUNTIF(ENERO!$H$3:$H$100, C6)+COUNTIF(FEBRERO!$H$3:$H$100, C6)+COUNTIF(MARZO!$H$3:$H$100, C6)+COUNTIF(ABRIL!$H$3:$H$100, C6)+COUNTIF(MAYO!$H$3:$H$100, C6)+COUNTIF(JUNIO!$H$3:$H$100, C6)+COUNTIF(JULIO!$H$3:$H$100, C6)+COUNTIF(AGOSTO!$H$3:$H$100, C6)+COUNTIF(SEPTIEMBRE!$H$3:$H$100, C6)+COUNTIF(OCTUBRE!$H$3:$H$100, C6)+COUNTIF(NOVIEMBRE!$H$3:$H$100, C6)+COUNTIF(DICIEMBRE!$H$3:$H$100, C6) -> 5 | F6: =SUMIFS(ENERO!$E$3:$E$100, ENERO!$H$3:$H$100, C6)+SUMIFS(FEBRERO!$E$3:$E$100, FEBRERO!$H$3:$H$100, C6)+SUMIFS(MARZO!$E$3:$E$100, MARZO!$H$3:$H$100, C6)+SUMIFS(ABRIL!$E$3:$E$100, ABRIL!$H$3:$H$100, C6)+SUMIFS(MAYO!$E$3:$E$100, MAYO!$H$3:$H$100, C6)+SUMIFS(JUNIO!$E$3:$E$100, JUNIO!$H$3:$H$100, C6)+SUMIFS(JULIO!$E$3:$E$100, JULIO!$H$3:$H$100, C6)+SUMIFS(AGOSTO!$E$3:$E$100, AGOSTO!$H$3:$H$100, C6)+SUMIFS(SEPTIEMBRE!$E$3:$E$100, SEPTIEMBRE!$H$3:$H$100, C6)+SUMIFS(OCTUBRE!$E$3:$E$100, OCTUBRE!$H$3:$H$100, C6)+SUMIFS(NOVIEMBRE!$E$3:$E$100, NOVIEMBRE!$H$3:$H$100, C6)+SUMIFS(DICIEMBRE!$E$3:$E$100, DICIEMBRE!$H$3:$H$100, C6) -> 12200 | G6: =IF(E6>=2, "Frecuente", "Único") -> Frecuente
B7: CLI-002 | C7: Nick | D7: 13058137201 | E7: =COUNTIF(ENERO!$H$3:$H$100, C7)+COUNTIF(FEBRERO!$H$3:$H$100, C7)+COUNTIF(MARZO!$H$3:$H$100, C7)+COUNTIF(ABRIL!$H$3:$H$100, C7)+COUNTIF(MAYO!$H$3:$H$100, C7)+COUNTIF(JUNIO!$H$3:$H$100, C7)+COUNTIF(JULIO!$H$3:$H$100, C7)+COUNTIF(AGOSTO!$H$3:$H$100, C7)+COUNTIF(SEPTIEMBRE!$H$3:$H$100, C7)+COUNTIF(OCTUBRE!$H$3:$H$100, C7)+COUNTIF(NOVIEMBRE!$H$3:$H$100, C7)+COUNTIF(DICIEMBRE!$H$3:$H$100, C7) -> 4 | F7: =SUMIFS(ENERO!$E$3:$E$100, ENERO!$H$3:$H$100, C7)+SUMIFS(FEBRERO!$E$3:$E$100, FEBRERO!$H$3:$H$100, C7)+SUMIFS(MARZO!$E$3:$E$100, MARZO!$H$3:$H$100, C7)+SUMIFS(ABRIL!$E$3:$E$100, ABRIL!$H$3:$H$100, C7)+SUMIFS(MAYO!$E$3:$E$100, MAYO!$H$3:$H$100, C7)+SUMIFS(JUNIO!$E$3:$E$100, JUNIO!$H$3:$H$100, C7)+SUMIFS(JULIO!$E$3:$E$100, JULIO!$H$3:$H$100, C7)+SUMIFS(AGOSTO!$E$3:$E$100, AGOSTO!$H$3:$H$100, C7)+SUMIFS(SEPTIEMBRE!$E$3:$E$100, SEPTIEMBRE!$H$3:$H$100, C7)+SUMIFS(OCTUBRE!$E$3:$E$100, OCTUBRE!$H$3:$H$100, C7)+SUMIFS(NOVIEMBRE!$E$3:$E$100, NOVIEMBRE!$H$3:$H$100, C7)+SUMIFS(DICIEMBRE!$E$3:$E$100, DICIEMBRE!$H$3:$H$100, C7) -> 8500 | G7: =IF(E7>=2, "Frecuente", "Único") -> Frecuente
B8: CLI-003 | C8: Angel | D8: 9842700484 | E8: =COUNTIF(ENERO!$H$3:$H$100, C8)+COUNTIF(FEBRERO!$H$3:$H$100, C8)+COUNTIF(MARZO!$H$3:$H$100, C8)+COUNTIF(ABRIL!$H$3:$H$100, C8)+COUNTIF(MAYO!$H$3:$H$100, C8)+COUNTIF(JUNIO!$H$3:$H$100, C8)+COUNTIF(JULIO!$H$3:$H$100, C8)+COUNTIF(AGOSTO!$H$3:$H$100, C8)+COUNTIF(SEPTIEMBRE!$H$3:$H$100, C8)+COUNTIF(OCTUBRE!$H$3:$H$100, C8)+COUNTIF(NOVIEMBRE!$H$3:$H$100, C8)+COUNTIF(DICIEMBRE!$H$3:$H$100, C8) -> 3 | F8: =SUMIFS(ENERO!$E$3:$E$100, ENERO!$H$3:$H$100, C8)+SUMIFS(FEBRERO!$E$3:$E$100, FEBRERO!$H$3:$H$100, C8)+SUMIFS(MARZO!$E$3:$E$100, MARZO!$H$3:$H$100, C8)+SUMIFS(ABRIL!$E$3:$E$100, ABRIL!$H$3:$H$100, C8)+SUMIFS(MAYO!$E$3:$E$100, MAYO!$H$3:$H$100, C8)+SUMIFS(JUNIO!$E$3:$E$100, JUNIO!$H$3:$H$100, C8)+SUMIFS(JULIO!$E$3:$E$100, JULIO!$H$3:$H$100, C8)+SUMIFS(AGOSTO!$E$3:$E$100, AGOSTO!$H$3:$H$100, C8)+SUMIFS(SEPTIEMBRE!$E$3:$E$100, SEPTIEMBRE!$H$3:$H$100, C8)+SUMIFS(OCTUBRE!$E$3:$E$100, OCTUBRE!$H$3:$H$100, C8)+SUMIFS(NOVIEMBRE!$E$3:$E$100, NOVIEMBRE!$H$3:$H$100, C8)+SUMIFS(DICIEMBRE!$E$3:$E$100, DICIEMBRE!$H$3:$H$100, C8) -> 7250 | G8: =IF(E8>=2, "Frecuente", "Único") -> Frecuente
B9: CLI-004 | C9: Adalid | D9: 5559076452 | E9: =COUNTIF(ENERO!$H$3:$H$100, C9)+COUNTIF(FEBRERO!$H$3:$H$100, C9)+COUNTIF(MARZO!$H$3:$H$100, C9)+COUNTIF(ABRIL!$H$3:$H$100, C9)+COUNTIF(MAYO!$H$3:$H$100, C9)+COUNTIF(JUNIO!$H$3:$H$100, C9)+COUNTIF(JULIO!$H$3:$H$100, C9)+COUNTIF(AGOSTO!$H$3:$H$100, C9)+COUNTIF(SEPTIEMBRE!$H$3:$H$100, C9)+COUNTIF(OCTUBRE!$H$3:$H$100, C9)+COUNTIF(NOVIEMBRE!$H$3:$H$100, C9)+COUNTIF(DICIEMBRE!$H$3:$H$100, C9) -> 2 | F9: =SUMIFS(ENERO!$E$3:$E$100, ENERO!$H$3:$H$100, C9)+SUMIFS(FEBRERO!$E$3:$E$100, FEBRERO!$H$3:$H$100, C9)+SUMIFS(MARZO!$E$3:$E$100, MARZO!$H$3:$H$100, C9)+SUMIFS(ABRIL!$E$3:$E$100, ABRIL!$H$3:$H$100, C9)+SUMIFS(MAYO!$E$3:$E$100, MAYO!$H$3:$H$100, C9)+SUMIFS(JUNIO!$E$3:$E$100, JUNIO!$H$3:$H$100, C9)+SUMIFS(JULIO!$E$3:$E$100, JULIO!$H$3:$H$100, C9)+SUMIFS(AGOSTO!$E$3:$E$100, AGOSTO!$H$3:$H$100, C9)+SUMIFS(SEPTIEMBRE!$E$3:$E$100, SEPTIEMBRE!$H$3:$H$100, C9)+SUMIFS(OCTUBRE!$E$3:$E$100, OCTUBRE!$H$3:$H$100, C9)+SUMIFS(NOVIEMBRE!$E$3:$E$100, NOVIEMBRE!$H$3:$H$100, C9)+SUMIFS(DICIEMBRE!$E$3:$E$100, DICIEMBRE!$H$3:$H$100, C9) -> 4800 | G9: =IF(E9>=2, "Frecuente", "Único") -> Frecuente
B10: CLI-005 | C10: Fredrerick | D10: 16044467115 | E10: =COUNTIF(ENERO!$H$3:$H$100, C10)+COUNTIF(FEBRERO!$H$3:$H$100, C10)+COUNTIF(MARZO!$H$3:$H$100, C10)+COUNTIF(ABRIL!$H$3:$H$100, C10)+COUNTIF(MAYO!$H$3:$H$100, C10)+COUNTIF(JUNIO!$H$3:$H$100, C10)+COUNTIF(JULIO!$H$3:$H$100, C10)+COUNTIF(AGOSTO!$H$3:$H$100, C10)+COUNTIF(SEPTIEMBRE!$H$3:$H$100, C10)+COUNTIF(OCTUBRE!$H$3:$H$100, C10)+COUNTIF(NOVIEMBRE!$H$3:$H$100, C10)+COUNTIF(DICIEMBRE!$H$3:$H$100, C10) -> 2 | F10: =SUMIFS(ENERO!$E$3:$E$100, ENERO!$H$3:$H$100, C10)+SUMIFS(FEBRERO!$E$3:$E$100, FEBRERO!$H$3:$H$100, C10)+SUMIFS(MARZO!$E$3:$E$100, MARZO!$H$3:$H$100, C10)+SUMIFS(ABRIL!$E$3:$E$100, ABRIL!$H$3:$H$100, C10)+SUMIFS(MAYO!$E$3:$E$100, MAYO!$H$3:$H$100, C10)+SUMIFS(JUNIO!$E$3:$E$100, JUNIO!$H$3:$H$100, C10)+SUMIFS(JULIO!$E$3:$E$100, JULIO!$H$3:$H$100, C10)+SUMIFS(AGOSTO!$E$3:$E$100, AGOSTO!$H$3:$H$100, C10)+SUMIFS(SEPTIEMBRE!$E$3:$E$100, SEPTIEMBRE!$H$3:$H$100, C10)+SUMIFS(OCTUBRE!$E$3:$E$100, OCTUBRE!$H$3:$H$100, C10)+SUMIFS(NOVIEMBRE!$E$3:$E$100, NOVIEMBRE!$H$3:$H$100, C10)+SUMIFS(DICIEMBRE!$E$3:$E$100, DICIEMBRE!$H$3:$H$100, C10) -> 12000 | G10: =IF(E10>=2, "Frecuente", "Único") -> Frecuente
B11: CLI-006 | C11: Jody | D11: 14123535223 | E11: =COUNTIF(ENERO!$H$3:$H$100, C11)+COUNTIF(FEBRERO!$H$3:$H$100, C11)+COUNTIF(MARZO!$H$3:$H$100, C11)+COUNTIF(ABRIL!$H$3:$H$100, C11)+COUNTIF(MAYO!$H$3:$H$100, C11)+COUNTIF(JUNIO!$H$3:$H$100, C11)+COUNTIF(JULIO!$H$3:$H$100, C11)+COUNTIF(AGOSTO!$H$3:$H$100, C11)+COUNTIF(SEPTIEMBRE!$H$3:$H$100, C11)+COUNTIF(OCTUBRE!$H$3:$H$100, C11)+COUNTIF(NOVIEMBRE!$H$3:$H$100, C11)+COUNTIF(DICIEMBRE!$H$3:$H$100, C11) -> 2 | F11: =SUMIFS(ENERO!$E$3:$E$100, ENERO!$H$3:$H$100, C11)+SUMIFS(FEBRERO!$E$3:$E$100, FEBRERO!$H$3:$H$100, C11)+SUMIFS(MARZO!$E$3:$E$100, MARZO!$H$3:$H$100, C11)+SUMIFS(ABRIL!$E$3:$E$100, ABRIL!$H$3:$H$100, C11)+SUMIFS(MAYO!$E$3:$E$100, MAYO!$H$3:$H$100, C11)+SUMIFS(JUNIO!$E$3:$E$100, JUNIO!$H$3:$H$100, C11)+SUMIFS(JULIO!$E$3:$E$100, JULIO!$H$3:$H$100, C11)+SUMIFS(AGOSTO!$E$3:$E$100, AGOSTO!$H$3:$H$100, C11)+SUMIFS(SEPTIEMBRE!$E$3:$E$100, SEPTIEMBRE!$H$3:$H$100, C11)+SUMIFS(OCTUBRE!$E$3:$E$100, OCTUBRE!$H$3:$H$100, C11)+SUMIFS(NOVIEMBRE!$E$3:$E$100, NOVIEMBRE!$H$3:$H$100, C11)+SUMIFS(DICIEMBRE!$E$3:$E$100, DICIEMBRE!$H$3:$H$100, C11) -> 5000 | G11: =IF(E11>=2, "Frecuente", "Único") -> Frecuente
B12: CLI-007 | C12: Marco | D12: 9841854234 | E12: =COUNTIF(ENERO!$H$3:$H$100, C12)+COUNTIF(FEBRERO!$H$3:$H$100, C12)+COUNTIF(MARZO!$H$3:$H$100, C12)+COUNTIF(ABRIL!$H$3:$H$100, C12)+COUNTIF(MAYO!$H$3:$H$100, C12)+COUNTIF(JUNIO!$H$3:$H$100, C12)+COUNTIF(JULIO!$H$3:$H$100, C12)+COUNTIF(AGOSTO!$H$3:$H$100, C12)+COUNTIF(SEPTIEMBRE!$H$3:$H$100, C12)+COUNTIF(OCTUBRE!$H$3:$H$100, C12)+COUNTIF(NOVIEMBRE!$H$3:$H$100, C12)+COUNTIF(DICIEMBRE!$H$3:$H$100, C12) -> 2 | F12: =SUMIFS(ENERO!$E$3:$E$100, ENERO!$H$3:$H$100, C12)+SUMIFS(FEBRERO!$E$3:$E$100, FEBRERO!$H$3:$H$100, C12)+SUMIFS(MARZO!$E$3:$E$100, MARZO!$H$3:$H$100, C12)+SUMIFS(ABRIL!$E$3:$E$100, ABRIL!$H$3:$H$100, C12)+SUMIFS(MAYO!$E$3:$E$100, MAYO!$H$3:$H$100, C12)+SUMIFS(JUNIO!$E$3:$E$100, JUNIO!$H$3:$H$100, C12)+SUMIFS(JULIO!$E$3:$E$100, JULIO!$H$3:$H$100, C12)+SUMIFS(AGOSTO!$E$3:$E$100, AGOSTO!$H$3:$H$100, C12)+SUMIFS(SEPTIEMBRE!$E$3:$E$100, SEPTIEMBRE!$H$3:$H$100, C12)+SUMIFS(OCTUBRE!$E$3:$E$100, OCTUBRE!$H$3:$H$100, C12)+SUMIFS(NOVIEMBRE!$E$3:$E$100, NOVIEMBRE!$H$3:$H$100, C12)+SUMIFS(DICIEMBRE!$E$3:$E$100, DICIEMBRE!$H$3:$H$100, C12) -> 5100 | G12: =IF(E12>=2, "Frecuente", "Único") -> Frecuente
B13: CLI-008 | C13: Mike | D13: 5514788867 | E13: =COUNTIF(ENERO!$H$3:$H$100, C13)+COUNTIF(FEBRERO!$H$3:$H$100, C13)+COUNTIF(MARZO!$H$3:$H$100, C13)+COUNTIF(ABRIL!$H$3:$H$100, C13)+COUNTIF(MAYO!$H$3:$H$100, C13)+COUNTIF(JUNIO!$H$3:$H$100, C13)+COUNTIF(JULIO!$H$3:$H$100, C13)+COUNTIF(AGOSTO!$H$3:$H$100, C13)+COUNTIF(SEPTIEMBRE!$H$3:$H$100, C13)+COUNTIF(OCTUBRE!$H$3:$H$100, C13)+COUNTIF(NOVIEMBRE!$H$3:$H$100, C13)+COUNTIF(DICIEMBRE!$H$3:$H$100, C13) -> 2 | F13: =SUMIFS(ENERO!$E$3:$E$100, ENERO!$H$3:$H$100, C13)+SUMIFS(FEBRERO!$E$3:$E$100, FEBRERO!$H$3:$H$100, C13)+SUMIFS(MARZO!$E$3:$E$100, MARZO!$H$3:$H$100, C13)+SUMIFS(ABRIL!$E$3:$E$100, ABRIL!$H$3:$H$100, C13)+SUMIFS(MAYO!$E$3:$E$100, MAYO!$H$3:$H$100, C13)+SUMIFS(JUNIO!$E$3:$E$100, JUNIO!$H$3:$H$100, C13)+SUMIFS(JULIO!$E$3:$E$100, JULIO!$H$3:$H$100, C13)+SUMIFS(AGOSTO!$E$3:$E$100, AGOSTO!$H$3:$H$100, C13)+SUMIFS(SEPTIEMBRE!$E$3:$E$100, SEPTIEMBRE!$H$3:$H$100, C13)+SUMIFS(OCTUBRE!$E$3:$E$100, OCTUBRE!$H$3:$H$100, C13)+SUMIFS(NOVIEMBRE!$E$3:$E$100, NOVIEMBRE!$H$3:$H$100, C13)+SUMIFS(DICIEMBRE!$E$3:$E$100, DICIEMBRE!$H$3:$H$100, C13) -> 12000 | G13: =IF(E13>=2, "Frecuente", "Único") -> Frecuente
B14: CLI-009 | C14: Philippe | D14: 6317451792 | E14: =COUNTIF(ENERO!$H$3:$H$100, C14)+COUNTIF(FEBRERO!$H$3:$H$100, C14)+COUNTIF(MARZO!$H$3:$H$100, C14)+COUNTIF(ABRIL!$H$3:$H$100, C14)+COUNTIF(MAYO!$H$3:$H$100, C14)+COUNTIF(JUNIO!$H$3:$H$100, C14)+COUNTIF(JULIO!$H$3:$H$100, C14)+COUNTIF(AGOSTO!$H$3:$H$100, C14)+COUNTIF(SEPTIEMBRE!$H$3:$H$100, C14)+COUNTIF(OCTUBRE!$H$3:$H$100, C14)+COUNTIF(NOVIEMBRE!$H$3:$H$100, C14)+COUNTIF(DICIEMBRE!$H$3:$H$100, C14) -> 2 | F14: =SUMIFS(ENERO!$E$3:$E$100, ENERO!$H$3:$H$100, C14)+SUMIFS(FEBRERO!$E$3:$E$100, FEBRERO!$H$3:$H$100, C14)+SUMIFS(MARZO!$E$3:$E$100, MARZO!$H$3:$H$100, C14)+SUMIFS(ABRIL!$E$3:$E$100, ABRIL!$H$3:$H$100, C14)+SUMIFS(MAYO!$E$3:$E$100, MAYO!$H$3:$H$100, C14)+SUMIFS(JUNIO!$E$3:$E$100, JUNIO!$H$3:$H$100, C14)+SUMIFS(JULIO!$E$3:$E$100, JULIO!$H$3:$H$100, C14)+SUMIFS(AGOSTO!$E$3:$E$100, AGOSTO!$H$3:$H$100, C14)+SUMIFS(SEPTIEMBRE!$E$3:$E$100, SEPTIEMBRE!$H$3:$H$100, C14)+SUMIFS(OCTUBRE!$E$3:$E$100, OCTUBRE!$H$3:$H$100, C14)+SUMIFS(NOVIEMBRE!$E$3:$E$100, NOVIEMBRE!$H$3:$H$100, C14)+SUMIFS(DICIEMBRE!$E$3:$E$100, DICIEMBRE!$H$3:$H$100, C14) -> 12000 | G14: =IF(E14>=2, "Frecuente", "Único") -> Frecuente
B15: CLI-010 | C15: Urvan | D15: 5560318920 | E15: =COUNTIF(ENERO!$H$3:$H$100, C15)+COUNTIF(FEBRERO!$H$3:$H$100, C15)+COUNTIF(MARZO!$H$3:$H$100, C15)+COUNTIF(ABRIL!$H$3:$H$100, C15)+COUNTIF(MAYO!$H$3:$H$100, C15)+COUNTIF(JUNIO!$H$3:$H$100, C15)+COUNTIF(JULIO!$H$3:$H$100, C15)+COUNTIF(AGOSTO!$H$3:$H$100, C15)+COUNTIF(SEPTIEMBRE!$H$3:$H$100, C15)+COUNTIF(OCTUBRE!$H$3:$H$100, C15)+COUNTIF(NOVIEMBRE!$H$3:$H$100, C15)+COUNTIF(DICIEMBRE!$H$3:$H$100, C15) -> 2 | F15: =SUMIFS(ENERO!$E$3:$E$100, ENERO!$H$3:$H$100, C15)+SUMIFS(FEBRERO!$E$3:$E$100, FEBRERO!$H$3:$H$100, C15)+SUMIFS(MARZO!$E$3:$E$100, MARZO!$H$3:$H$100, C15)+SUMIFS(ABRIL!$E$3:$E$100, ABRIL!$H$3:$H$100, C15)+SUMIFS(MAYO!$E$3:$E$100, MAYO!$H$3:$H$100, C15)+SUMIFS(JUNIO!$E$3:$E$100, JUNIO!$H$3:$H$100, C15)+SUMIFS(JULIO!$E$3:$E$100, JULIO!$H$3:$H$100, C15)+SUMIFS(AGOSTO!$E$3:$E$100, AGOSTO!$H$3:$H$100, C15)+SUMIFS(SEPTIEMBRE!$E$3:$E$100, SEPTIEMBRE!$H$3:$H$100, C15)+SUMIFS(OCTUBRE!$E$3:$E$100, OCTUBRE!$H$3:$H$100, C15)+SUMIFS(NOVIEMBRE!$E$3:$E$100, NOVIEMBRE!$H$3:$H$100, C15)+SUMIFS(DICIEMBRE!$E$3:$E$100, DICIEMBRE!$H$3:$H$100, C15) -> 10000 | G15: =IF(E15>=2, "Frecuente", "Único") -> Frecuente
B16: CLI-011 | C16: Vanny | D16: 9848064005 | E16: =COUNTIF(ENERO!$H$3:$H$100, C16)+COUNTIF(FEBRERO!$H$3:$H$100, C16)+COUNTIF(MARZO!$H$3:$H$100, C16)+COUNTIF(ABRIL!$H$3:$H$100, C16)+COUNTIF(MAYO!$H$3:$H$100, C16)+COUNTIF(JUNIO!$H$3:$H$100, C16)+COUNTIF(JULIO!$H$3:$H$100, C16)+COUNTIF(AGOSTO!$H$3:$H$100, C16)+COUNTIF(SEPTIEMBRE!$H$3:$H$100, C16)+COUNTIF(OCTUBRE!$H$3:$H$100, C16)+COUNTIF(NOVIEMBRE!$H$3:$H$100, C16)+COUNTIF(DICIEMBRE!$H$3:$H$100, C16) -> 2 | F16: =SUMIFS(ENERO!$E$3:$E$100, ENERO!$H$3:$H$100, C16)+SUMIFS(FEBRERO!$E$3:$E$100, FEBRERO!$H$3:$H$100, C16)+SUMIFS(MARZO!$E$3:$E$100, MARZO!$H$3:$H$100, C16)+SUMIFS(ABRIL!$E$3:$E$100, ABRIL!$H$3:$H$100, C16)+SUMIFS(MAYO!$E$3:$E$100, MAYO!$H$3:$H$100, C16)+SUMIFS(JUNIO!$E$3:$E$100, JUNIO!$H$3:$H$100, C16)+SUMIFS(JULIO!$E$3:$E$100, JULIO!$H$3:$H$100, C16)+SUMIFS(AGOSTO!$E$3:$E$100, AGOSTO!$H$3:$H$100, C16)+SUMIFS(SEPTIEMBRE!$E$3:$E$100, SEPTIEMBRE!$H$3:$H$100, C16)+SUMIFS(OCTUBRE!$E$3:$E$100, OCTUBRE!$H$3:$H$100, C16)+SUMIFS(NOVIEMBRE!$E$3:$E$100, NOVIEMBRE!$H$3:$H$100, C16)+SUMIFS(DICIEMBRE!$E$3:$E$100, DICIEMBRE!$H$3:$H$100, C16) -> 5000 | G16: =IF(E16>=2, "Frecuente", "Único") -> Frecuente
B17: CLI-012 | C17: Adri | D17: 9842650711 | E17: =COUNTIF(ENERO!$H$3:$H$100, C17)+COUNTIF(FEBRERO!$H$3:$H$100, C17)+COUNTIF(MARZO!$H$3:$H$100, C17)+COUNTIF(ABRIL!$H$3:$H$100, C17)+COUNTIF(MAYO!$H$3:$H$100, C17)+COUNTIF(JUNIO!$H$3:$H$100, C17)+COUNTIF(JULIO!$H$3:$H$100, C17)+COUNTIF(AGOSTO!$H$3:$H$100, C17)+COUNTIF(SEPTIEMBRE!$H$3:$H$100, C17)+COUNTIF(OCTUBRE!$H$3:$H$100, C17)+COUNTIF(NOVIEMBRE!$H$3:$H$100, C17)+COUNTIF(DICIEMBRE!$H$3:$H$100, C17) -> 1 | F17: =SUMIFS(ENERO!$E$3:$E$100, ENERO!$H$3:$H$100, C17)+SUMIFS(FEBRERO!$E$3:$E$100, FEBRERO!$H$3:$H$100, C17)+SUMIFS(MARZO!$E$3:$E$100, MARZO!$H$3:$H$100, C17)+SUMIFS(ABRIL!$E$3:$E$100, ABRIL!$H$3:$H$100, C17)+SUMIFS(MAYO!$E$3:$E$100, MAYO!$H$3:$H$100, C17)+SUMIFS(JUNIO!$E$3:$E$100, JUNIO!$H$3:$H$100, C17)+SUMIFS(JULIO!$E$3:$E$100, JULIO!$H$3:$H$100, C17)+SUMIFS(AGOSTO!$E$3:$E$100, AGOSTO!$H$3:$H$100, C17)+SUMIFS(SEPTIEMBRE!$E$3:$E$100, SEPTIEMBRE!$H$3:$H$100, C17)+SUMIFS(OCTUBRE!$E$3:$E$100, OCTUBRE!$H$3:$H$100, C17)+SUMIFS(NOVIEMBRE!$E$3:$E$100, NOVIEMBRE!$H$3:$H$100, C17)+SUMIFS(DICIEMBRE!$E$3:$E$100, DICIEMBRE!$H$3:$H$100, C17) -> 1600 | G17: =IF(E17>=2, "Frecuente", "Único") -> Único
... B19: CLI-014 | C19: Alexa Kury | D19: 9843222478 | E19: =COUNTIF(ENERO!$H$3:$H$100, C19)+COUNTIF(FEBRERO!$H$3:$H$100, C19)+COUNTIF(MARZO!$H$3:$H$100, C19)+COUNTIF(ABRIL!$H$3:$H$100, C19)+COUNTIF(MAYO!$H$3:$H$100, C19)+COUNTIF(JUNIO!$H$3:$H$100, C19)+COUNTIF(JULIO!$H$3:$H$100, C19)+COUNTIF(AGOSTO!$H$3:$H$100, C19)+COUNTIF(SEPTIEMBRE!$H$3:$H$100, C19)+COUNTIF(OCTUBRE!$H$3:$H$100, C19)+COUNTIF(NOVIEMBRE!$H$3:$H$100, C19)+COUNTIF(DICIEMBRE!$H$3:$H$100, C19) -> 1 | F19: =SUMIFS(ENERO!$E$3:$E$100, ENERO!$H$3:$H$100, C19)+SUMIFS(FEBRERO!$E$3:$E$100, FEBRERO!$H$3:$H$100, C19)+SUMIFS(MARZO!$E$3:$E$100, MARZO!$H$3:$H$100, C19)+SUMIFS(ABRIL!$E$3:$E$100, ABRIL!$H$3:$H$100, C19)+SUMIFS(MAYO!$E$3:$E$100, MAYO!$H$3:$H$100, C19)+SUMIFS(JUNIO!$E$3:$E$100, JUNIO!$H$3:$H$100, C19)+SUMIFS(JULIO!$E$3:$E$100, JULIO!$H$3:$H$100, C19)+SUMIFS(AGOSTO!$E$3:$E$100, AGOSTO!$H$3:$H$100, C19)+SUMIFS(SEPTIEMBRE!$E$3:$E$100, SEPTIEMBRE!$H$3:$H$100, C19)+SUMIFS(OCTUBRE!$E$3:$E$100, OCTUBRE!$H$3:$H$100, C19)+SUMIFS(NOVIEMBRE!$E$3:$E$100, NOVIEMBRE!$H$3:$H$100, C19)+SUMIFS(DICIEMBRE!$E$3:$E$100, DICIEMBRE!$H$3:$H$100, C19) -> 1750 | G19: =IF(E19>=2, "Frecuente", "Único") -> Único
B20: CLI-015 | C20: Alexis Michigan | E20: =COUNTIF(ENERO!$H$3:$H$100, C20)+COUNTIF(FEBRERO!$H$3:$H$100, C20)+COUNTIF(MARZO!$H$3:$H$100, C20)+COUNTIF(ABRIL!$H$3:$H$100, C20)+COUNTIF(MAYO!$H$3:$H$100, C20)+COUNTIF(JUNIO!$H$3:$H$100, C20)+COUNTIF(JULIO!$H$3:$H$100, C20)+COUNTIF(AGOSTO!$H$3:$H$100, C20)+COUNTIF(SEPTIEMBRE!$H$3:$H$100, C20)+COUNTIF(OCTUBRE!$H$3:$H$100, C20)+COUNTIF(NOVIEMBRE!$H$3:$H$100, C20)+COUNTIF(DICIEMBRE!$H$3:$H$100, C20) -> 1 | F20: =SUMIFS(ENERO!$E$3:$E$100, ENERO!$H$3:$H$100, C20)+SUMIFS(FEBRERO!$E$3:$E$100, FEBRERO!$H$3:$H$100, C20)+SUMIFS(MARZO!$E$3:$E$100, MARZO!$H$3:$H$100, C20)+SUMIFS(ABRIL!$E$3:$E$100, ABRIL!$H$3:$H$100, C20)+SUMIFS(MAYO!$E$3:$E$100, MAYO!$H$3:$H$100, C20)+SUMIFS(JUNIO!$E$3:$E$100, JUNIO!$H$3:$H$100, C20)+SUMIFS(JULIO!$E$3:$E$100, JULIO!$H$3:$H$100, C20)+SUMIFS(AGOSTO!$E$3:$E$100, AGOSTO!$H$3:$H$100, C20)+SUMIFS(SEPTIEMBRE!$E$3:$E$100, SEPTIEMBRE!$H$3:$H$100, C20)+SUMIFS(OCTUBRE!$E$3:$E$100, OCTUBRE!$H$3:$H$100, C20)+SUMIFS(NOVIEMBRE!$E$3:$E$100, NOVIEMBRE!$H$3:$H$100, C20)+SUMIFS(DICIEMBRE!$E$3:$E$100, DICIEMBRE!$H$3:$H$100, C20) -> 2000 | G20: =IF(E20>=2, "Frecuente", "Único") -> Único
B21: CLI-016 | C21: Ana | D21: 9842117136 | E21: =COUNTIF(ENERO!$H$3:$H$100, C21)+COUNTIF(FEBRERO!$H$3:$H$100, C21)+COUNTIF(MARZO!$H$3:$H$100, C21)+COUNTIF(ABRIL!$H$3:$H$100, C21)+COUNTIF(MAYO!$H$3:$H$100, C21)+COUNTIF(JUNIO!$H$3:$H$100, C21)+COUNTIF(JULIO!$H$3:$H$100, C21)+COUNTIF(AGOSTO!$H$3:$H$100, C21)+COUNTIF(SEPTIEMBRE!$H$3:$H$100, C21)+COUNTIF(OCTUBRE!$H$3:$H$100, C21)+COUNTIF(NOVIEMBRE!$H$3:$H$100, C21)+COUNTIF(DICIEMBRE!$H$3:$H$100, C21) -> 1 | F21: =SUMIFS(ENERO!$E$3:$E$100, ENERO!$H$3:$H$100, C21)+SUMIFS(FEBRERO!$E$3:$E$100, FEBRERO!$H$3:$H$100, C21)+SUMIFS(MARZO!$E$3:$E$100, MARZO!$H$3:$H$100, C21)+SUMIFS(ABRIL!$E$3:$E$100, ABRIL!$H$3:$H$100, C21)+SUMIFS(MAYO!$E$3:$E$100, MAYO!$H$3:$H$100, C21)+SUMIFS(JUNIO!$E$3:$E$100, JUNIO!$H$3:$H$100, C21)+SUMIFS(JULIO!$E$3:$E$100, JULIO!$H$3:$H$100, C21)+SUMIFS(AGOSTO!$E$3:$E$100, AGOSTO!$H$3:$H$100, C21)+SUMIFS(SEPTIEMBRE!$E$3:$E$100, SEPTIEMBRE!$H$3:$H$100, C21)+SUMIFS(OCTUBRE!$E$3:$E$100, OCTUBRE!$H$3:$H$100, C21)+SUMIFS(NOVIEMBRE!$E$3:$E$100, NOVIEMBRE!$H$3:$H$100, C21)+SUMIFS(DICIEMBRE!$E$3:$E$100, DICIEMBRE!$H$3:$H$100, C21) -> 3000 | G21: =IF(E21>=2, "Frecuente", "Único") -> Único
B22: CLI-017 | C22: Angela | D22: 9841319791 | E22: =COUNTIF(ENERO!$H$3:$H$100, C22)+COUNTIF(FEBRERO!$H$3:$H$100, C22)+COUNTIF(MARZO!$H$3:$H$100, C22)+COUNTIF(ABRIL!$H$3:$H$100, C22)+COUNTIF(MAYO!$H$3:$H$100, C22)+COUNTIF(JUNIO!$H$3:$H$100, C22)+COUNTIF(JULIO!$H$3:$H$100, C22)+COUNTIF(AGOSTO!$H$3:$H$100, C22)+COUNTIF(SEPTIEMBRE!$H$3:$H$100, C22)+COUNTIF(OCTUBRE!$H$3:$H$100, C22)+COUNTIF(NOVIEMBRE!$H$3:$H$100, C22)+COUNTIF(DICIEMBRE!$H$3:$H$100, C22) -> 1 | F22: =SUMIFS(ENERO!$E$3:$E$100, ENERO!$H$3:$H$100, C22)+SUMIFS(FEBRERO!$E$3:$E$100, FEBRERO!$H$3:$H$100, C22)+SUMIFS(MARZO!$E$3:$E$100, MARZO!$H$3:$H$100, C22)+SUMIFS(ABRIL!$E$3:$E$100, ABRIL!$H$3:$H$100, C22)+SUMIFS(MAYO!$E$3:$E$100, MAYO!$H$3:$H$100, C22)+SUMIFS(JUNIO!$E$3:$E$100, JUNIO!$H$3:$H$100, C22)+SUMIFS(JULIO!$E$3:$E$100, JULIO!$H$3:$H$100, C22)+SUMIFS(AGOSTO!$E$3:$E$100, AGOSTO!$H$3:$H$100, C22)+SUMIFS(SEPTIEMBRE!$E$3:$E$100, SEPTIEMBRE!$H$3:$H$100, C22)+SUMIFS(OCTUBRE!$E$3:$E$100, OCTUBRE!$H$3:$H$100, C22)+SUMIFS(NOVIEMBRE!$E$3:$E$100, NOVIEMBRE!$H$3:$H$100, C22)+SUMIFS(DICIEMBRE!$E$3:$E$100, DICIEMBRE!$H$3:$H$100, C22) -> 1600 | G22: =IF(E22>=2, "Frecuente", "Único") -> Único
B23: CLI-018 | C23: Antonio Vecino | D23: 9842020009 | E23: =COUNTIF(ENERO!$H$3:$H$100, C23)+COUNTIF(FEBRERO!$H$3:$H$100, C23)+COUNTIF(MARZO!$H$3:$H$100, C23)+COUNTIF(ABRIL!$H$3:$H$100, C23)+COUNTIF(MAYO!$H$3:$H$100, C23)+COUNTIF(JUNIO!$H$3:$H$100, C23)+COUNTIF(JULIO!$H$3:$H$100, C23)+COUNTIF(AGOSTO!$H$3:$H$100, C23)+COUNTIF(SEPTIEMBRE!$H$3:$H$100, C23)+COUNTIF(OCTUBRE!$H$3:$H$100, C23)+COUNTIF(NOVIEMBRE!$H$3:$H$100, C23)+COUNTIF(DICIEMBRE!$H$3:$H$100, C23) -> 1 | F23: =SUMIFS(ENERO!$E$3:$E$100, ENERO!$H$3:$H$100, C23)+SUMIFS(FEBRERO!$E$3:$E$100, FEBRERO!$H$3:$H$100, C23)+SUMIFS(MARZO!$E$3:$E$100, MARZO!$H$3:$H$100, C23)+SUMIFS(ABRIL!$E$3:$E$100, ABRIL!$H$3:$H$100, C23)+SUMIFS(MAYO!$E$3:$E$100, MAYO!$H$3:$H$100, C23)+SUMIFS(JUNIO!$E$3:$E$100, JUNIO!$H$3:$H$100, C23)+SUMIFS(JULIO!$E$3:$E$100, JULIO!$H$3:$H$100, C23)+SUMIFS(AGOSTO!$E$3:$E$100, AGOSTO!$H$3:$H$100, C23)+SUMIFS(SEPTIEMBRE!$E$3:$E$100, SEPTIEMBRE!$H$3:$H$100, C23)+SUMIFS(OCTUBRE!$E$3:$E$100, OCTUBRE!$H$3:$H$100, C23)+SUMIFS(NOVIEMBRE!$E$3:$E$100, NOVIEMBRE!$H$3:$H$100, C23)+SUMIFS(DICIEMBRE!$E$3:$E$100, DICIEMBRE!$H$3:$H$100, C23) -> 6000 | G23: =IF(E23>=2, "Frecuente", "Único") -> Único
B24: CLI-019 | C24: Arely | E24: =COUNTIF(ENERO!$H$3:$H$100, C24)+COUNTIF(FEBRERO!$H$3:$H$100, C24)+COUNTIF(MARZO!$H$3:$H$100, C24)+COUNTIF(ABRIL!$H$3:$H$100, C24)+COUNTIF(MAYO!$H$3:$H$100, C24)+COUNTIF(JUNIO!$H$3:$H$100, C24)+COUNTIF(JULIO!$H$3:$H$100, C24)+COUNTIF(AGOSTO!$H$3:$H$100, C24)+COUNTIF(SEPTIEMBRE!$H$3:$H$100, C24)+COUNTIF(OCTUBRE!$H$3:$H$100, C24)+COUNTIF(NOVIEMBRE!$H$3:$H$100, C24)+COUNTIF(DICIEMBRE!$H$3:$H$100, C24) -> 1 | F24: =SUMIFS(ENERO!$E$3:$E$100, ENERO!$H$3:$H$100, C24)+SUMIFS(FEBRERO!$E$3:$E$100, FEBRERO!$H$3:$H$100, C24)+SUMIFS(MARZO!$E$3:$E$100, MARZO!$H$3:$H$100, C24)+SUMIFS(ABRIL!$E$3:$E$100, ABRIL!$H$3:$H$100, C24)+SUMIFS(MAYO!$E$3:$E$100, MAYO!$H$3:$H$100, C24)+SUMIFS(JUNIO!$E$3:$E$100, JUNIO!$H$3:$H$100, C24)+SUMIFS(JULIO!$E$3:$E$100, JULIO!$H$3:$H$100, C24)+SUMIFS(AGOSTO!$E$3:$E$100, AGOSTO!$H$3:$H$100, C24)+SUMIFS(SEPTIEMBRE!$E$3:$E$100, SEPTIEMBRE!$H$3:$H$100, C24)+SUMIFS(OCTUBRE!$E$3:$E$100, OCTUBRE!$H$3:$H$100, C24)+SUMIFS(NOVIEMBRE!$E$3:$E$100, NOVIEMBRE!$H$3:$H$100, C24)+SUMIFS(DICIEMBRE!$E$3:$E$100, DICIEMBRE!$H$3:$H$100, C24) -> 3200 | G24: =IF(E24>=2, "Frecuente", "Único") -> Único
B25: CLI-020 | C25: Arturo | D25: 9841662824 | E25: =COUNTIF(ENERO!$H$3:$H$100, C25)+COUNTIF(FEBRERO!$H$3:$H$100, C25)+COUNTIF(MARZO!$H$3:$H$100, C25)+COUNTIF(ABRIL!$H$3:$H$100, C25)+COUNTIF(MAYO!$H$3:$H$100, C25)+COUNTIF(JUNIO!$H$3:$H$100, C25)+COUNTIF(JULIO!$H$3:$H$100, C25)+COUNTIF(AGOSTO!$H$3:$H$100, C25)+COUNTIF(SEPTIEMBRE!$H$3:$H$100, C25)+COUNTIF(OCTUBRE!$H$3:$H$100, C25)+COUNTIF(NOVIEMBRE!$H$3:$H$100, C25)+COUNTIF(DICIEMBRE!$H$3:$H$100, C25) -> 1 | F25: =SUMIFS(ENERO!$E$3:$E$100, ENERO!$H$3:$H$100, C25)+SUMIFS(FEBRERO!$E$3:$E$100, FEBRERO!$H$3:$H$100, C25)+SUMIFS(MARZO!$E$3:$E$100, MARZO!$H$3:$H$100, C25)+SUMIFS(ABRIL!$E$3:$E$100, ABRIL!$H$3:$H$100, C25)+SUMIFS(MAYO!$E$3:$E$100, MAYO!$H$3:$H$100, C25)+SUMIFS(JUNIO!$E$3:$E$100, JUNIO!$H$3:$H$100, C25)+SUMIFS(JULIO!$E$3:$E$100, JULIO!$H$3:$H$100, C25)+SUMIFS(AGOSTO!$E$3:$E$100, AGOSTO!$H$3:$H$100, C25)+SUMIFS(SEPTIEMBRE!$E$3:$E$100, SEPTIEMBRE!$H$3:$H$100, C25)+SUMIFS(OCTUBRE!$E$3:$E$100, OCTUBRE!$H$3:$H$100, C25)+SUMIFS(NOVIEMBRE!$E$3:$E$100, NOVIEMBRE!$H$3:$H$100, C25)+SUMIFS(DICIEMBRE!$E$3:$E$100, DICIEMBRE!$H$3:$H$100, C25) -> 1600 | G25: =IF(E25>=2, "Frecuente", "Único") -> Único
B26: CLI-021 | C26: Atilio | E26: =COUNTIF(ENERO!$H$3:$H$100, C26)+COUNTIF(FEBRERO!$H$3:$H$100, C26)+COUNTIF(MARZO!$H$3:$H$100, C26)+COUNTIF(ABRIL!$H$3:$H$100, C26)+COUNTIF(MAYO!$H$3:$H$100, C26)+COUNTIF(JUNIO!$H$3:$H$100, C26)+COUNTIF(JULIO!$H$3:$H$100, C26)+COUNTIF(AGOSTO!$H$3:$H$100, C26)+COUNTIF(SEPTIEMBRE!$H$3:$H$100, C26)+COUNTIF(OCTUBRE!$H$3:$H$100, C26)+COUNTIF(NOVIEMBRE!$H$3:$H$100, C26)+COUNTIF(DICIEMBRE!$H$3:$H$100, C26) -> 1 | F26: =SUMIFS(ENERO!$E$3:$E$100, ENERO!$H$3:$H$100, C26)+SUMIFS(FEBRERO!$E$3:$E$100, FEBRERO!$H$3:$H$100, C26)+SUMIFS(MARZO!$E$3:$E$100, MARZO!$H$3:$H$100, C26)+SUMIFS(ABRIL!$E$3:$E$100, ABRIL!$H$3:$H$100, C26)+SUMIFS(MAYO!$E$3:$E$100, MAYO!$H$3:$H$100, C26)+SUMIFS(JUNIO!$E$3:$E$100, JUNIO!$H$3:$H$100, C26)+SUMIFS(JULIO!$E$3:$E$100, JULIO!$H$3:$H$100, C26)+SUMIFS(AGOSTO!$E$3:$E$100, AGOSTO!$H$3:$H$100, C26)+SUMIFS(SEPTIEMBRE!$E$3:$E$100, SEPTIEMBRE!$H$3:$H$100, C26)+SUMIFS(OCTUBRE!$E$3:$E$100, OCTUBRE!$H$3:$H$100, C26)+SUMIFS(NOVIEMBRE!$E$3:$E$100, NOVIEMBRE!$H$3:$H$100, C26)+SUMIFS(DICIEMBRE!$E$3:$E$100, DICIEMBRE!$H$3:$H$100, C26) -> 1600 | G26: =IF(E26>=2, "Frecuente", "Único") -> Único
B27: CLI-022 | C27: Belen | D27: 9847457693 | E27: =COUNTIF(ENERO!$H$3:$H$100, C27)+COUNTIF(FEBRERO!$H$3:$H$100, C27)+COUNTIF(MARZO!$H$3:$H$100, C27)+COUNTIF(ABRIL!$H$3:$H$100, C27)+COUNTIF(MAYO!$H$3:$H$100, C27)+COUNTIF(JUNIO!$H$3:$H$100, C27)+COUNTIF(JULIO!$H$3:$H$100, C27)+COUNTIF(AGOSTO!$H$3:$H$100, C27)+COUNTIF(SEPTIEMBRE!$H$3:$H$100, C27)+COUNTIF(OCTUBRE!$H$3:$H$100, C27)+COUNTIF(NOVIEMBRE!$H$3:$H$100, C27)+COUNTIF(DICIEMBRE!$H$3:$H$100, C27) -> 1 | F27: =SUMIFS(ENERO!$E$3:$E$100, ENERO!$H$3:$H$100, C27)+SUMIFS(FEBRERO!$E$3:$E$100, FEBRERO!$H$3:$H$100, C27)+SUMIFS(MARZO!$E$3:$E$100, MARZO!$H$3:$H$100, C27)+SUMIFS(ABRIL!$E$3:$E$100, ABRIL!$H$3:$H$100, C27)+SUMIFS(MAYO!$E$3:$E$100, MAYO!$H$3:$H$100, C27)+SUMIFS(JUNIO!$E$3:$E$100, JUNIO!$H$3:$H$100, C27)+SUMIFS(JULIO!$E$3:$E$100, JULIO!$H$3:$H$100, C27)+SUMIFS(AGOSTO!$E$3:$E$100, AGOSTO!$H$3:$H$100, C27)+SUMIFS(SEPTIEMBRE!$E$3:$E$100, SEPTIEMBRE!$H$3:$H$100, C27)+SUMIFS(OCTUBRE!$E$3:$E$100, OCTUBRE!$H$3:$H$100, C27)+SUMIFS(NOVIEMBRE!$E$3:$E$100, NOVIEMBRE!$H$3:$H$100, C27)+SUMIFS(DICIEMBRE!$E$3:$E$100, DICIEMBRE!$H$3:$H$100, C27) -> 3500 | G27: =IF(E27>=2, "Frecuente", "Único") -> Único
B28: CLI-023 | C28: Berthe | D28: 15142601561 | E28: =COUNTIF(ENERO!$H$3:$H$100, C28)+COUNTIF(FEBRERO!$H$3:$H$100, C28)+COUNTIF(MARZO!$H$3:$H$100, C28)+COUNTIF(ABRIL!$H$3:$H$100, C28)+COUNTIF(MAYO!$H$3:$H$100, C28)+COUNTIF(JUNIO!$H$3:$H$100, C28)+COUNTIF(JULIO!$H$3:$H$100, C28)+COUNTIF(AGOSTO!$H$3:$H$100, C28)+COUNTIF(SEPTIEMBRE!$H$3:$H$100, C28)+COUNTIF(OCTUBRE!$H$3:$H$100, C28)+COUNTIF(NOVIEMBRE!$H$3:$H$100, C28)+COUNTIF(DICIEMBRE!$H$3:$H$100, C28) -> 1 | F28: =SUMIFS(ENERO!$E$3:$E$100, ENERO!$H$3:$H$100, C28)+SUMIFS(FEBRERO!$E$3:$E$100, FEBRERO!$H$3:$H$100, C28)+SUMIFS(MARZO!$E$3:$E$100, MARZO!$H$3:$H$100, C28)+SUMIFS(ABRIL!$E$3:$E$100, ABRIL!$H$3:$H$100, C28)+SUMIFS(MAYO!$E$3:$E$100, MAYO!$H$3:$H$100, C28)+SUMIFS(JUNIO!$E$3:$E$100, JUNIO!$H$3:$H$100, C28)+SUMIFS(JULIO!$E$3:$E$100, JULIO!$H$3:$H$100, C28)+SUMIFS(AGOSTO!$E$3:$E$100, AGOSTO!$H$3:$H$100, C28)+SUMIFS(SEPTIEMBRE!$E$3:$E$100, SEPTIEMBRE!$H$3:$H$100, C28)+SUMIFS(OCTUBRE!$E$3:$E$100, OCTUBRE!$H$3:$H$100, C28)+SUMIFS(NOVIEMBRE!$E$3:$E$100, NOVIEMBRE!$H$3:$H$100, C28)+SUMIFS(DICIEMBRE!$E$3:$E$100, DICIEMBRE!$H$3:$H$100, C28) -> 1600 | G28: =IF(E28>=2, "Frecuente", "Único") -> Único
B29: CLI-024 | C29: Cande | D29: 9842392775 | E29: =COUNTIF(ENERO!$H$3:$H$100, C29)+COUNTIF(FEBRERO!$H$3:$H$100, C29)+COUNTIF(MARZO!$H$3:$H$100, C29)+COUNTIF(ABRIL!$H$3:$H$100, C29)+COUNTIF(MAYO!$H$3:$H$100, C29)+COUNTIF(JUNIO!$H$3:$H$100, C29)+COUNTIF(JULIO!$H$3:$H$100, C29)+COUNTIF(AGOSTO!$H$3:$H$100, C29)+COUNTIF(SEPTIEMBRE!$H$3:$H$100, C29)+COUNTIF(OCTUBRE!$H$3:$H$100, C29)+COUNTIF(NOVIEMBRE!$H$3:$H$100, C29)+COUNTIF(DICIEMBRE!$H$3:$H$100, C29) -> 1 | F29: =SUMIFS(ENERO!$E$3:$E$100, ENERO!$H$3:$H$100, C29)+SUMIFS(FEBRERO!$E$3:$E$100, FEBRERO!$H$3:$H$100, C29)+SUMIFS(MARZO!$E$3:$E$100, MARZO!$H$3:$H$100, C29)+SUMIFS(ABRIL!$E$3:$E$100, ABRIL!$H$3:$H$100, C29)+SUMIFS(MAYO!$E$3:$E$100, MAYO!$H$3:$H$100, C29)+SUMIFS(JUNIO!$E$3:$E$100, JUNIO!$H$3:$H$100, C29)+SUMIFS(JULIO!$E$3:$E$100, JULIO!$H$3:$H$100, C29)+SUMIFS(AGOSTO!$E$3:$E$100, AGOSTO!$H$3:$H$100, C29)+SUMIFS(SEPTIEMBRE!$E$3:$E$100, SEPTIEMBRE!$H$3:$H$100, C29)+SUMIFS(OCTUBRE!$E$3:$E$100, OCTUBRE!$H$3:$H$100, C29)+SUMIFS(NOVIEMBRE!$E$3:$E$100, NOVIEMBRE!$H$3:$H$100, C29)+SUMIFS(DICIEMBRE!$E$3:$E$100, DICIEMBRE!$H$3:$H$100, C29) -> 6000 | G29: =IF(E29>=2, "Frecuente", "Único") -> Único
B30: CLI-025 | C30: Ctle Cozumel | E30: =COUNTIF(ENERO!$H$3:$H$100, C30)+COUNTIF(FEBRERO!$H$3:$H$100, C30)+COUNTIF(MARZO!$H$3:$H$100, C30)+COUNTIF(ABRIL!$H$3:$H$100, C30)+COUNTIF(MAYO!$H$3:$H$100, C30)+COUNTIF(JUNIO!$H$3:$H$100, C30)+COUNTIF(JULIO!$H$3:$H$100, C30)+COUNTIF(AGOSTO!$H$3:$H$100, C30)+COUNTIF(SEPTIEMBRE!$H$3:$H$100, C30)+COUNTIF(OCTUBRE!$H$3:$H$100, C30)+COUNTIF(NOVIEMBRE!$H$3:$H$100, C30)+COUNTIF(DICIEMBRE!$H$3:$H$100, C30) -> 1 | F30: =SUMIFS(ENERO!$E$3:$E$100, ENERO!$H$3:$H$100, C30)+SUMIFS(FEBRERO!$E$3:$E$100, FEBRERO!$H$3:$H$100, C30)+SUMIFS(MARZO!$E$3:$E$100, MARZO!$H$3:$H$100, C30)+SUMIFS(ABRIL!$E$3:$E$100, ABRIL!$H$3:$H$100, C30)+SUMIFS(MAYO!$E$3:$E$100, MAYO!$H$3:$H$100, C30)+SUMIFS(JUNIO!$E$3:$E$100, JUNIO!$H$3:$H$100, C30)+SUMIFS(JULIO!$E$3:$E$100, JULIO!$H$3:$H$100, C30)+SUMIFS(AGOSTO!$E$3:$E$100, AGOSTO!$H$3:$H$100, C30)+SUMIFS(SEPTIEMBRE!$E$3:$E$100, SEPTIEMBRE!$H$3:$H$100, C30)+SUMIFS(OCTUBRE!$E$3:$E$100, OCTUBRE!$H$3:$H$100, C30)+SUMIFS(NOVIEMBRE!$E$3:$E$100, NOVIEMBRE!$H$3:$H$100, C30)+SUMIFS(DICIEMBRE!$E$3:$E$100, DICIEMBRE!$H$3:$H$100, C30) -> 1800 | G30: =IF(E30>=2, "Frecuente", "Único") -> Único
B31: CLI-026 | C31: Dani | D31: 9843190040 | E31: =COUNTIF(ENERO!$H$3:$H$100, C31)+COUNTIF(FEBRERO!$H$3:$H$100, C31)+COUNTIF(MARZO!$H$3:$H$100, C31)+COUNTIF(ABRIL!$H$3:$H$100, C31)+COUNTIF(MAYO!$H$3:$H$100, C31)+COUNTIF(JUNIO!$H$3:$H$100, C31)+COUNTIF(JULIO!$H$3:$H$100, C31)+COUNTIF(AGOSTO!$H$3:$H$100, C31)+COUNTIF(SEPTIEMBRE!$H$3:$H$100, C31)+COUNTIF(OCTUBRE!$H$3:$H$100, C31)+COUNTIF(NOVIEMBRE!$H$3:$H$100, C31)+COUNTIF(DICIEMBRE!$H$3:$H$100, C31) -> 1 | F31: =SUMIFS(ENERO!$E$3:$E$100, ENERO!$H$3:$H$100, C31)+SUMIFS(FEBRERO!$E$3:$E$100, FEBRERO!$H$3:$H$100, C31)+SUMIFS(MARZO!$E$3:$E$100, MARZO!$H$3:$H$100, C31)+SUMIFS(ABRIL!$E$3:$E$100, ABRIL!$H$3:$H$100, C31)+SUMIFS(MAYO!$E$3:$E$100, MAYO!$H$3:$H$100, C31)+SUMIFS(JUNIO!$E$3:$E$100, JUNIO!$H$3:$H$100, C31)+SUMIFS(JULIO!$E$3:$E$100, JULIO!$H$3:$H$100, C31)+SUMIFS(AGOSTO!$E$3:$E$100, AGOSTO!$H$3:$H$100, C31)+SUMIFS(SEPTIEMBRE!$E$3:$E$100, SEPTIEMBRE!$H$3:$H$100, C31)+SUMIFS(OCTUBRE!$E$3:$E$100, OCTUBRE!$H$3:$H$100, C31)+SUMIFS(NOVIEMBRE!$E$3:$E$100, NOVIEMBRE!$H$3:$H$100, C31)+SUMIFS(DICIEMBRE!$E$3:$E$100, DICIEMBRE!$H$3:$H$100, C31) -> 4800 | G31: =IF(E31>=2, "Frecuente", "Único") -> Único
B32: CLI-027 | C32: Diana | D32: 9842085522 | E32: =COUNTIF(ENERO!$H$3:$H$100, C32)+COUNTIF(FEBRERO!$H$3:$H$100, C32)+COUNTIF(MARZO!$H$3:$H$100, C32)+COUNTIF(ABRIL!$H$3:$H$100, C32)+COUNTIF(MAYO!$H$3:$H$100, C32)+COUNTIF(JUNIO!$H$3:$H$100, C32)+COUNTIF(JULIO!$H$3:$H$100, C32)+COUNTIF(AGOSTO!$H$3:$H$100, C32)+COUNTIF(SEPTIEMBRE!$H$3:$H$100, C32)+COUNTIF(OCTUBRE!$H$3:$H$100, C32)+COUNTIF(NOVIEMBRE!$H$3:$H$100, C32)+COUNTIF(DICIEMBRE!$H$3:$H$100, C32) -> 1 | F32: =SUMIFS(ENERO!$E$3:$E$100, ENERO!$H$3:$H$100, C32)+SUMIFS(FEBRERO!$E$3:$E$100, FEBRERO!$H$3:$H$100, C32)+SUMIFS(MARZO!$E$3:$E$100, MARZO!$H$3:$H$100, C32)+SUMIFS(ABRIL!$E$3:$E$100, ABRIL!$H$3:$H$100, C32)+SUMIFS(MAYO!$E$3:$E$100, MAYO!$H$3:$H$100, C32)+SUMIFS(JUNIO!$E$3:$E$100, JUNIO!$H$3:$H$100, C32)+SUMIFS(JULIO!$E$3:$E$100, JULIO!$H$3:$H$100, C32)+SUMIFS(AGOSTO!$E$3:$E$100, AGOSTO!$H$3:$H$100, C32)+SUMIFS(SEPTIEMBRE!$E$3:$E$100, SEPTIEMBRE!$H$3:$H$100, C32)+SUMIFS(OCTUBRE!$E$3:$E$100, OCTUBRE!$H$3:$H$100, C32)+SUMIFS(NOVIEMBRE!$E$3:$E$100, NOVIEMBRE!$H$3:$H$100, C32)+SUMIFS(DICIEMBRE!$E$3:$E$100, DICIEMBRE!$H$3:$H$100, C32) -> 700 | G32: =IF(E32>=2, "Frecuente", "Único") -> Único
B33: CLI-028 | C33: Didier | D33: 15144315412 | E33: =COUNTIF(ENERO!$H$3:$H$100, C33)+COUNTIF(FEBRERO!$H$3:$H$100, C33)+COUNTIF(MARZO!$H$3:$H$100, C33)+COUNTIF(ABRIL!$H$3:$H$100, C33)+COUNTIF(MAYO!$H$3:$H$100, C33)+COUNTIF(JUNIO!$H$3:$H$100, C33)+COUNTIF(JULIO!$H$3:$H$100, C33)+COUNTIF(AGOSTO!$H$3:$H$100, C33)+COUNTIF(SEPTIEMBRE!$H$3:$H$100, C33)+COUNTIF(OCTUBRE!$H$3:$H$100, C33)+COUNTIF(NOVIEMBRE!$H$3:$H$100, C33)+COUNTIF(DICIEMBRE!$H$3:$H$100, C33) -> 1 | F33: =SUMIFS(ENERO!$E$3:$E$100, ENERO!$H$3:$H$100, C33)+SUMIFS(FEBRERO!$E$3:$E$100, FEBRERO!$H$3:$H$100, C33)+SUMIFS(MARZO!$E$3:$E$100, MARZO!$H$3:$H$100, C33)+SUMIFS(ABRIL!$E$3:$E$100, ABRIL!$H$3:$H$100, C33)+SUMIFS(MAYO!$E$3:$E$100, MAYO!$H$3:$H$100, C33)+SUMIFS(JUNIO!$E$3:$E$100, JUNIO!$H$3:$H$100, C33)+SUMIFS(JULIO!$E$3:$E$100, JULIO!$H$3:$H$100, C33)+SUMIFS(AGOSTO!$E$3:$E$100, AGOSTO!$H$3:$H$100, C33)+SUMIFS(SEPTIEMBRE!$E$3:$E$100, SEPTIEMBRE!$H$3:$H$100, C33)+SUMIFS(OCTUBRE!$E$3:$E$100, OCTUBRE!$H$3:$H$100, C33)+SUMIFS(NOVIEMBRE!$E$3:$E$100, NOVIEMBRE!$H$3:$H$100, C33)+SUMIFS(DICIEMBRE!$E$3:$E$100, DICIEMBRE!$H$3:$H$100, C33) -> 1600 | G33: =IF(E33>=2, "Frecuente", "Único") -> Único
B34: CLI-029 | C34: Edgar Santana | D34: 3329045164 | E34: =COUNTIF(ENERO!$H$3:$H$100, C34)+COUNTIF(FEBRERO!$H$3:$H$100, C34)+COUNTIF(MARZO!$H$3:$H$100, C34)+COUNTIF(ABRIL!$H$3:$H$100, C34)+COUNTIF(MAYO!$H$3:$H$100, C34)+COUNTIF(JUNIO!$H$3:$H$100, C34)+COUNTIF(JULIO!$H$3:$H$100, C34)+COUNTIF(AGOSTO!$H$3:$H$100, C34)+COUNTIF(SEPTIEMBRE!$H$3:$H$100, C34)+COUNTIF(OCTUBRE!$H$3:$H$100, C34)+COUNTIF(NOVIEMBRE!$H$3:$H$100, C34)+COUNTIF(DICIEMBRE!$H$3:$H$100, C34) -> 1 | F34: =SUMIFS(ENERO!$E$3:$E$100, ENERO!$H$3:$H$100, C34)+SUMIFS(FEBRERO!$E$3:$E$100, FEBRERO!$H$3:$H$100, C34)+SUMIFS(MARZO!$E$3:$E$100, MARZO!$H$3:$H$100, C34)+SUMIFS(ABRIL!$E$3:$E$100, ABRIL!$H$3:$H$100, C34)+SUMIFS(MAYO!$E$3:$E$100, MAYO!$H$3:$H$100, C34)+SUMIFS(JUNIO!$E$3:$E$100, JUNIO!$H$3:$H$100, C34)+SUMIFS(JULIO!$E$3:$E$100, JULIO!$H$3:$H$100, C34)+SUMIFS(AGOSTO!$E$3:$E$100, AGOSTO!$H$3:$H$100, C34)+SUMIFS(SEPTIEMBRE!$E$3:$E$100, SEPTIEMBRE!$H$3:$H$100, C34)+SUMIFS(OCTUBRE!$E$3:$E$100, OCTUBRE!$H$3:$H$100, C34)+SUMIFS(NOVIEMBRE!$E$3:$E$100, NOVIEMBRE!$H$3:$H$100, C34)+SUMIFS(DICIEMBRE!$E$3:$E$100, DICIEMBRE!$H$3:$H$100, C34) -> 3200 | G34: =IF(E34>=2, "Frecuente", "Único") -> Único
B35: CLI-030 | C35: Efrain | D35: 9841989317 | E35: =COUNTIF(ENERO!$H$3:$H$100, C35)+COUNTIF(FEBRERO!$H$3:$H$100, C35)+COUNTIF(MARZO!$H$3:$H$100, C35)+COUNTIF(ABRIL!$H$3:$H$100, C35)+COUNTIF(MAYO!$H$3:$H$100, C35)+COUNTIF(JUNIO!$H$3:$H$100, C35)+COUNTIF(JULIO!$H$3:$H$100, C35)+COUNTIF(AGOSTO!$H$3:$H$100, C35)+COUNTIF(SEPTIEMBRE!$H$3:$H$100, C35)+COUNTIF(OCTUBRE!$H$3:$H$100, C35)+COUNTIF(NOVIEMBRE!$H$3:$H$100, C35)+COUNTIF(DICIEMBRE!$H$3:$H$100, C35) -> 1 | F35: =SUMIFS(ENERO!$E$3:$E$100, ENERO!$H$3:$H$100, C35)+SUMIFS(FEBRERO!$E$3:$E$100, FEBRERO!$H$3:$H$100, C35)+SUMIFS(MARZO!$E$3:$E$100, MARZO!$H$3:$H$100, C35)+SUMIFS(ABRIL!$E$3:$E$100, ABRIL!$H$3:$H$100, C35)+SUMIFS(MAYO!$E$3:$E$100, MAYO!$H$3:$H$100, C35)+SUMIFS(JUNIO!$E$3:$E$100, JUNIO!$H$3:$H$100, C35)+SUMIFS(JULIO!$E$3:$E$100, JULIO!$H$3:$H$100, C35)+SUMIFS(AGOSTO!$E$3:$E$100, AGOSTO!$H$3:$H$100, C35)+SUMIFS(SEPTIEMBRE!$E$3:$E$100, SEPTIEMBRE!$H$3:$H$100, C35)+SUMIFS(OCTUBRE!$E$3:$E$100, OCTUBRE!$H$3:$H$100, C35)+SUMIFS(NOVIEMBRE!$E$3:$E$100, NOVIEMBRE!$H$3:$H$100, C35)+SUMIFS(DICIEMBRE!$E$3:$E$100, DICIEMBRE!$H$3:$H$100, C35) -> 3500 | G35: =IF(E35>=2, "Frecuente", "Único") -> Único
B36: CLI-031 | C36: Eric | D36: 9841886970 | E36: =COUNTIF(ENERO!$H$3:$H$100, C36)+COUNTIF(FEBRERO!$H$3:$H$100, C36)+COUNTIF(MARZO!$H$3:$H$100, C36)+COUNTIF(ABRIL!$H$3:$H$100, C36)+COUNTIF(MAYO!$H$3:$H$100, C36)+COUNTIF(JUNIO!$H$3:$H$100, C36)+COUNTIF(JULIO!$H$3:$H$100, C36)+COUNTIF(AGOSTO!$H$3:$H$100, C36)+COUNTIF(SEPTIEMBRE!$H$3:$H$100, C36)+COUNTIF(OCTUBRE!$H$3:$H$100, C36)+COUNTIF(NOVIEMBRE!$H$3:$H$100, C36)+COUNTIF(DICIEMBRE!$H$3:$H$100, C36) -> 1 | F36: =SUMIFS(ENERO!$E$3:$E$100, ENERO!$H$3:$H$100, C36)+SUMIFS(FEBRERO!$E$3:$E$100, FEBRERO!$H$3:$H$100, C36)+SUMIFS(MARZO!$E$3:$E$100, MARZO!$H$3:$H$100, C36)+SUMIFS(ABRIL!$E$3:$E$100, ABRIL!$H$3:$H$100, C36)+SUMIFS(MAYO!$E$3:$E$100, MAYO!$H$3:$H$100, C36)+SUMIFS(JUNIO!$E$3:$E$100, JUNIO!$H$3:$H$100, C36)+SUMIFS(JULIO!$E$3:$E$100, JULIO!$H$3:$H$100, C36)+SUMIFS(AGOSTO!$E$3:$E$100, AGOSTO!$H$3:$H$100, C36)+SUMIFS(SEPTIEMBRE!$E$3:$E$100, SEPTIEMBRE!$H$3:$H$100, C36)+SUMIFS(OCTUBRE!$E$3:$E$100, OCTUBRE!$H$3:$H$100, C36)+SUMIFS(NOVIEMBRE!$E$3:$E$100, NOVIEMBRE!$H$3:$H$100, C36)+SUMIFS(DICIEMBRE!$E$3:$E$100, DICIEMBRE!$H$3:$H$100, C36) -> 3500 | G36: =IF(E36>=2, "Frecuente", "Único") -> Único
B37: CLI-032 | C37: Esteban | D37: 9844827425 | E37: =COUNTIF(ENERO!$H$3:$H$100, C37)+COUNTIF(FEBRERO!$H$3:$H$100, C37)+COUNTIF(MARZO!$H$3:$H$100, C37)+COUNTIF(ABRIL!$H$3:$H$100, C37)+COUNTIF(MAYO!$H$3:$H$100, C37)+COUNTIF(JUNIO!$H$3:$H$100, C37)+COUNTIF(JULIO!$H$3:$H$100, C37)+COUNTIF(AGOSTO!$H$3:$H$100, C37)+COUNTIF(SEPTIEMBRE!$H$3:$H$100, C37)+COUNTIF(OCTUBRE!$H$3:$H$100, C37)+COUNTIF(NOVIEMBRE!$H$3:$H$100, C37)+COUNTIF(DICIEMBRE!$H$3:$H$100, C37) -> 1 | F37: =SUMIFS(ENERO!$E$3:$E$100, ENERO!$H$3:$H$100, C37)+SUMIFS(FEBRERO!$E$3:$E$100, FEBRERO!$H$3:$H$100, C37)+SUMIFS(MARZO!$E$3:$E$100, MARZO!$H$3:$H$100, C37)+SUMIFS(ABRIL!$E$3:$E$100, ABRIL!$H$3:$H$100, C37)+SUMIFS(MAYO!$E$3:$E$100, MAYO!$H$3:$H$100, C37)+SUMIFS(JUNIO!$E$3:$E$100, JUNIO!$H$3:$H$100, C37)+SUMIFS(JULIO!$E$3:$E$100, JULIO!$H$3:$H$100, C37)+SUMIFS(AGOSTO!$E$3:$E$100, AGOSTO!$H$3:$H$100, C37)+SUMIFS(SEPTIEMBRE!$E$3:$E$100, SEPTIEMBRE!$H$3:$H$100, C37)+SUMIFS(OCTUBRE!$E$3:$E$100, OCTUBRE!$H$3:$H$100, C37)+SUMIFS(NOVIEMBRE!$E$3:$E$100, NOVIEMBRE!$H$3:$H$100, C37)+SUMIFS(DICIEMBRE!$E$3:$E$100, DICIEMBRE!$H$3:$H$100, C37) -> 1600 | G37: =IF(E37>=2, "Frecuente", "Único") -> Único
B38: CLI-033 | C38: Evan | D38: 9934154000 | E38: =COUNTIF(ENERO!$H$3:$H$100, C38)+COUNTIF(FEBRERO!$H$3:$H$100, C38)+COUNTIF(MARZO!$H$3:$H$100, C38)+COUNTIF(ABRIL!$H$3:$H$100, C38)+COUNTIF(MAYO!$H$3:$H$100, C38)+COUNTIF(JUNIO!$H$3:$H$100, C38)+COUNTIF(JULIO!$H$3:$H$100, C38)+COUNTIF(AGOSTO!$H$3:$H$100, C38)+COUNTIF(SEPTIEMBRE!$H$3:$H$100, C38)+COUNTIF(OCTUBRE!$H$3:$H$100, C38)+COUNTIF(NOVIEMBRE!$H$3:$H$100, C38)+COUNTIF(DICIEMBRE!$H$3:$H$100, C38) -> 1 | F38: =SUMIFS(ENERO!$E$3:$E$100, ENERO!$H$3:$H$100, C38)+SUMIFS(FEBRERO!$E$3:$E$100, FEBRERO!$H$3:$H$100, C38)+SUMIFS(MARZO!$E$3:$E$100, MARZO!$H$3:$H$100, C38)+SUMIFS(ABRIL!$E$3:$E$100, ABRIL!$H$3:$H$100, C38)+SUMIFS(MAYO!$E$3:$E$100, MAYO!$H$3:$H$100, C38)+SUMIFS(JUNIO!$E$3:$E$100, JUNIO!$H$3:$H$100, C38)+SUMIFS(JULIO!$E$3:$E$100, JULIO!$H$3:$H$100, C38)+SUMIFS(AGOSTO!$E$3:$E$100, AGOSTO!$H$3:$H$100, C38)+SUMIFS(SEPTIEMBRE!$E$3:$E$100, SEPTIEMBRE!$H$3:$H$100, C38)+SUMIFS(OCTUBRE!$E$3:$E$100, OCTUBRE!$H$3:$H$100, C38)+SUMIFS(NOVIEMBRE!$E$3:$E$100, NOVIEMBRE!$H$3:$H$100, C38)+SUMIFS(DICIEMBRE!$E$3:$E$100, DICIEMBRE!$H$3:$H$100, C38) -> 12000 | G38: =IF(E38>=2, "Frecuente", "Único") -> Único
B39: CLI-034 | C39: Gabo | D39: 9844141833 | E39: =COUNTIF(ENERO!$H$3:$H$100, C39)+COUNTIF(FEBRERO!$H$3:$H$100, C39)+COUNTIF(MARZO!$H$3:$H$100, C39)+COUNTIF(ABRIL!$H$3:$H$100, C39)+COUNTIF(MAYO!$H$3:$H$100, C39)+COUNTIF(JUNIO!$H$3:$H$100, C39)+COUNTIF(JULIO!$H$3:$H$100, C39)+COUNTIF(AGOSTO!$H$3:$H$100, C39)+COUNTIF(SEPTIEMBRE!$H$3:$H$100, C39)+COUNTIF(OCTUBRE!$H$3:$H$100, C39)+COUNTIF(NOVIEMBRE!$H$3:$H$100, C39)+COUNTIF(DICIEMBRE!$H$3:$H$100, C39) -> 1 | F39: =SUMIFS(ENERO!$E$3:$E$100, ENERO!$H$3:$H$100, C39)+SUMIFS(FEBRERO!$E$3:$E$100, FEBRERO!$H$3:$H$100, C39)+SUMIFS(MARZO!$E$3:$E$100, MARZO!$H$3:$H$100, C39)+SUMIFS(ABRIL!$E$3:$E$100, ABRIL!$H$3:$H$100, C39)+SUMIFS(MAYO!$E$3:$E$100, MAYO!$H$3:$H$100, C39)+SUMIFS(JUNIO!$E$3:$E$100, JUNIO!$H$3:$H$100, C39)+SUMIFS(JULIO!$E$3:$E$100, JULIO!$H$3:$H$100, C39)+SUMIFS(AGOSTO!$E$3:$E$100, AGOSTO!$H$3:$H$100, C39)+SUMIFS(SEPTIEMBRE!$E$3:$E$100, SEPTIEMBRE!$H$3:$H$100, C39)+SUMIFS(OCTUBRE!$E$3:$E$100, OCTUBRE!$H$3:$H$100, C39)+SUMIFS(NOVIEMBRE!$E$3:$E$100, NOVIEMBRE!$H$3:$H$100, C39)+SUMIFS(DICIEMBRE!$E$3:$E$100, DICIEMBRE!$H$3:$H$100, C39) -> 3000 | G39: =IF(E39>=2, "Frecuente", "Único") -> Único
B40: CLI-035 | C40: Gore | D40: 2382728177 | E40: =COUNTIF(ENERO!$H$3:$H$100, C40)+COUNTIF(FEBRERO!$H$3:$H$100, C40)+COUNTIF(MARZO!$H$3:$H$100, C40)+COUNTIF(ABRIL!$H$3:$H$100, C40)+COUNTIF(MAYO!$H$3:$H$100, C40)+COUNTIF(JUNIO!$H$3:$H$100, C40)+COUNTIF(JULIO!$H$3:$H$100, C40)+COUNTIF(AGOSTO!$H$3:$H$100, C40)+COUNTIF(SEPTIEMBRE!$H$3:$H$100, C40)+COUNTIF(OCTUBRE!$H$3:$H$100, C40)+COUNTIF(NOVIEMBRE!$H$3:$H$100, C40)+COUNTIF(DICIEMBRE!$H$3:$H$100, C40) -> 1 | F40: =SUMIFS(ENERO!$E$3:$E$100, ENERO!$H$3:$H$100, C40)+SUMIFS(FEBRERO!$E$3:$E$100, FEBRERO!$H$3:$H$100, C40)+SUMIFS(MARZO!$E$3:$E$100, MARZO!$H$3:$H$100, C40)+SUMIFS(ABRIL!$E$3:$E$100, ABRIL!$H$3:$H$100, C40)+SUMIFS(MAYO!$E$3:$E$100, MAYO!$H$3:$H$100, C40)+SUMIFS(JUNIO!$E$3:$E$100, JUNIO!$H$3:$H$100, C40)+SUMIFS(JULIO!$E$3:$E$100, JULIO!$H$3:$H$100, C40)+SUMIFS(AGOSTO!$E$3:$E$100, AGOSTO!$H$3:$H$100, C40)+SUMIFS(SEPTIEMBRE!$E$3:$E$100, SEPTIEMBRE!$H$3:$H$100, C40)+SUMIFS(OCTUBRE!$E$3:$E$100, OCTUBRE!$H$3:$H$100, C40)+SUMIFS(NOVIEMBRE!$E$3:$E$100, NOVIEMBRE!$H$3:$H$100, C40)+SUMIFS(DICIEMBRE!$E$3:$E$100, DICIEMBRE!$H$3:$H$100, C40) -> 3000 | G40: =IF(E40>=2, "Frecuente", "Único") -> Único
B41: CLI-036 | C41: Hayyim | D41: 9843146554 | E41: =COUNTIF(ENERO!$H$3:$H$100, C41)+COUNTIF(FEBRERO!$H$3:$H$100, C41)+COUNTIF(MARZO!$H$3:$H$100, C41)+COUNTIF(ABRIL!$H$3:$H$100, C41)+COUNTIF(MAYO!$H$3:$H$100, C41)+COUNTIF(JUNIO!$H$3:$H$100, C41)+COUNTIF(JULIO!$H$3:$H$100, C41)+COUNTIF(AGOSTO!$H$3:$H$100, C41)+COUNTIF(SEPTIEMBRE!$H$3:$H$100, C41)+COUNTIF(OCTUBRE!$H$3:$H$100, C41)+COUNTIF(NOVIEMBRE!$H$3:$H$100, C41)+COUNTIF(DICIEMBRE!$H$3:$H$100, C41) -> 1 | F41: =SUMIFS(ENERO!$E$3:$E$100, ENERO!$H$3:$H$100, C41)+SUMIFS(FEBRERO!$E$3:$E$100, FEBRERO!$H$3:$H$100, C41)+SUMIFS(MARZO!$E$3:$E$100, MARZO!$H$3:$H$100, C41)+SUMIFS(ABRIL!$E$3:$E$100, ABRIL!$H$3:$H$100, C41)+SUMIFS(MAYO!$E$3:$E$100, MAYO!$H$3:$H$100, C41)+SUMIFS(JUNIO!$E$3:$E$100, JUNIO!$H$3:$H$100, C41)+SUMIFS(JULIO!$E$3:$E$100, JULIO!$H$3:$H$100, C41)+SUMIFS(AGOSTO!$E$3:$E$100, AGOSTO!$H$3:$H$100, C41)+SUMIFS(SEPTIEMBRE!$E$3:$E$100, SEPTIEMBRE!$H$3:$H$100, C41)+SUMIFS(OCTUBRE!$E$3:$E$100, OCTUBRE!$H$3:$H$100, C41)+SUMIFS(NOVIEMBRE!$E$3:$E$100, NOVIEMBRE!$H$3:$H$100, C41)+SUMIFS(DICIEMBRE!$E$3:$E$100, DICIEMBRE!$H$3:$H$100, C41) -> 1600 | G41: =IF(E41>=2, "Frecuente", "Único") -> Único
B42: CLI-037 | C42: Ivan Mtz | D42: 5534176800 | E42: =COUNTIF(ENERO!$H$3:$H$100, C42)+COUNTIF(FEBRERO!$H$3:$H$100, C42)+COUNTIF(MARZO!$H$3:$H$100, C42)+COUNTIF(ABRIL!$H$3:$H$100, C42)+COUNTIF(MAYO!$H$3:$H$100, C42)+COUNTIF(JUNIO!$H$3:$H$100, C42)+COUNTIF(JULIO!$H$3:$H$100, C42)+COUNTIF(AGOSTO!$H$3:$H$100, C42)+COUNTIF(SEPTIEMBRE!$H$3:$H$100, C42)+COUNTIF(OCTUBRE!$H$3:$H$100, C42)+COUNTIF(NOVIEMBRE!$H$3:$H$100, C42)+COUNTIF(DICIEMBRE!$H$3:$H$100, C42) -> 1 | F42: =SUMIFS(ENERO!$E$3:$E$100, ENERO!$H$3:$H$100, C42)+SUMIFS(FEBRERO!$E$3:$E$100, FEBRERO!$H$3:$H$100, C42)+SUMIFS(MARZO!$E$3:$E$100, MARZO!$H$3:$H$100, C42)+SUMIFS(ABRIL!$E$3:$E$100, ABRIL!$H$3:$H$100, C42)+SUMIFS(MAYO!$E$3:$E$100, MAYO!$H$3:$H$100, C42)+SUMIFS(JUNIO!$E$3:$E$100, JUNIO!$H$3:$H$100, C42)+SUMIFS(JULIO!$E$3:$E$100, JULIO!$H$3:$H$100, C42)+SUMIFS(AGOSTO!$E$3:$E$100, AGOSTO!$H$3:$H$100, C42)+SUMIFS(SEPTIEMBRE!$E$3:$E$100, SEPTIEMBRE!$H$3:$H$100, C42)+SUMIFS(OCTUBRE!$E$3:$E$100, OCTUBRE!$H$3:$H$100, C42)+SUMIFS(NOVIEMBRE!$E$3:$E$100, NOVIEMBRE!$H$3:$H$100, C42)+SUMIFS(DICIEMBRE!$E$3:$E$100, DICIEMBRE!$H$3:$H$100, C42) -> 6500 | G42: =IF(E42>=2, "Frecuente", "Único") -> Único
B43: CLI-038 | C43: Javier | E43: =COUNTIF(ENERO!$H$3:$H$100, C43)+COUNTIF(FEBRERO!$H$3:$H$100, C43)+COUNTIF(MARZO!$H$3:$H$100, C43)+COUNTIF(ABRIL!$H$3:$H$100, C43)+COUNTIF(MAYO!$H$3:$H$100, C43)+COUNTIF(JUNIO!$H$3:$H$100, C43)+COUNTIF(JULIO!$H$3:$H$100, C43)+COUNTIF(AGOSTO!$H$3:$H$100, C43)+COUNTIF(SEPTIEMBRE!$H$3:$H$100, C43)+COUNTIF(OCTUBRE!$H$3:$H$100, C43)+COUNTIF(NOVIEMBRE!$H$3:$H$100, C43)+COUNTIF(DICIEMBRE!$H$3:$H$100, C43) -> 1 | F43: =SUMIFS(ENERO!$E$3:$E$100, ENERO!$H$3:$H$100, C43)+SUMIFS(FEBRERO!$E$3:$E$100, FEBRERO!$H$3:$H$100, C43)+SUMIFS(MARZO!$E$3:$E$100, MARZO!$H$3:$H$100, C43)+SUMIFS(ABRIL!$E$3:$E$100, ABRIL!$H$3:$H$100, C43)+SUMIFS(MAYO!$E$3:$E$100, MAYO!$H$3:$H$100, C43)+SUMIFS(JUNIO!$E$3:$E$100, JUNIO!$H$3:$H$100, C43)+SUMIFS(JULIO!$E$3:$E$100, JULIO!$H$3:$H$100, C43)+SUMIFS(AGOSTO!$E$3:$E$100, AGOSTO!$H$3:$H$100, C43)+SUMIFS(SEPTIEMBRE!$E$3:$E$100, SEPTIEMBRE!$H$3:$H$100, C43)+SUMIFS(OCTUBRE!$E$3:$E$100, OCTUBRE!$H$3:$H$100, C43)+SUMIFS(NOVIEMBRE!$E$3:$E$100, NOVIEMBRE!$H$3:$H$100, C43)+SUMIFS(DICIEMBRE!$E$3:$E$100, DICIEMBRE!$H$3:$H$100, C43) -> 3000 | G43: =IF(E43>=2, "Frecuente", "Único") -> Único
...

Sheet ENERO
B1: Enero 2026
B2: DIA | C2: TRABAJO | D2: ARTISTA | E2: TOTAL | F2: TIP | G2: PORCENTAJE | H2: NOMBRE CLIENTE | I2: CONTACTO CLIENTE | J2: COMISIÓN ARTISTA | K2: NETO ESTUDIO
B3: 1 | C3: TATTOO | D3: VONY | E3: 1700 | G3: 0.5 | H3: Moises | I3: 9932052632 | J3: =IF(AND(ISNUMBER(E3), ISNUMBER(G3)), E3*(1-G3), 0) -> 850 | K3: =IF(AND(ISNUMBER(E3), ISNUMBER(G3)), E3*G3, 0) -> 850
B4: 3 | C4: TATTOO | D4: VONY | E4: 1600 | F4: 200 | G4: 0.5 | H4: Angela | I4: 9841319791 | J4: =IF(AND(ISNUMBER(E4), ISNUMBER(G4)), E4*(1-G4), 0) -> 800 | K4: =IF(AND(ISNUMBER(E4), ISNUMBER(G4)), E4*G4, 0) -> 800
B5: 3 | C5: PIERCING | D5: VONY | E5: 800 | G5: 0.5 | J5: =IF(AND(ISNUMBER(E5), ISNUMBER(G5)), E5*(1-G5), 0) -> 400 | K5: =IF(AND(ISNUMBER(E5), ISNUMBER(G5)), E5*G5, 0) -> 400
B6: 4 | C6: TATTOO | D6: DAVID | E6: 2000 | G6: 0.45 | J6: =IF(AND(ISNUMBER(E6), ISNUMBER(G6)), E6*(1-G6), 0) -> 1100 | K6: =IF(AND(ISNUMBER(E6), ISNUMBER(G6)), E6*G6, 0) -> 900
B7: 8 | C7: TATTOO | D7: DAVID | E7: 7500 | G7: 0.5 | J7: =IF(AND(ISNUMBER(E7), ISNUMBER(G7)), E7*(1-G7), 0) -> 3750 | K7: =IF(AND(ISNUMBER(E7), ISNUMBER(G7)), E7*G7, 0) -> 3750
B8: 12 | C8: TATTOO | D8: DAVID | E8: 3500 | G8: 0.5 | J8: =IF(AND(ISNUMBER(E8), ISNUMBER(G8)), E8*(1-G8), 0) -> 1750 | K8: =IF(AND(ISNUMBER(E8), ISNUMBER(G8)), E8*G8, 0) -> 1750
B9: 15 | C9: TATTOO | D9: DAVID | E9: 4500 | G9: 0.5 | J9: =IF(AND(ISNUMBER(E9), ISNUMBER(G9)), E9*(1-G9), 0) -> 2250 | K9: =IF(AND(ISNUMBER(E9), ISNUMBER(G9)), E9*G9, 0) -> 2250
B10: 15 | C10: TATTOO | D10: VONY | E10: 3000 | G10: 0.5 | H10: Emmanuel | I10: 9842712892 | J10: =IF(AND(ISNUMBER(E10), ISNUMBER(G10)), E10*(1-G10), 0) -> 1500 | K10: =IF(AND(ISNUMBER(E10), ISNUMBER(G10)), E10*G10, 0) -> 1500
B11: 16 | C11: TATTOO | D11: VONY | E11: 3000 | G11: 0.5 | H11: Gore | I11: 2382728177 | J11: =IF(AND(ISNUMBER(E11), ISNUMBER(G11)), E11*(1-G11), 0) -> 1500 | K11: =IF(AND(ISNUMBER(E11), ISNUMBER(G11)), E11*G11, 0) -> 1500
B12: 17 | C12: TATTOO | D12: DAVID | E12: 5500 | G12: 0.3 | J12: =IF(AND(ISNUMBER(E12), ISNUMBER(G12)), E12*(1-G12), 0) -> 3850 | K12: =IF(AND(ISNUMBER(E12), ISNUMBER(G12)), E12*G12, 0) -> 1650
B13: 18 | C13: TATTOO | D13: VONY | E13: 4000 | G13: 0.5 | H13: Yiyo | I13: 7755931712 | J13: =IF(AND(ISNUMBER(E13), ISNUMBER(G13)), E13*(1-G13), 0) -> 2000 | K13: =IF(AND(ISNUMBER(E13), ISNUMBER(G13)), E13*G13, 0) -> 2000
B14: 21 | C14: TATTOO | D14: VONY | E14: 12000 | G14: 0.5 | H14: Evan | I14: 9934154000 | J14: =IF(AND(ISNUMBER(E14), ISNUMBER(G14)), E14*(1-G14), 0) -> 6000 | K14: =IF(AND(ISNUMBER(E14), ISNUMBER(G14)), E14*G14, 0) -> 6000
B15: 22 | C15: TATTOO | D15: VONY | E15: 1600 | F15: 100 | G15: 0.5 | H15: Berthe | I15: 15142601561 | J15: =IF(AND(ISNUMBER(E15), ISNUMBER(G15)), E15*(1-G15), 0) -> 800 | K15: =IF(AND(ISNUMBER(E15), ISNUMBER(G15)), E15*G15, 0) -> 800
B16: 24 | C16: TATTOO | D16: VONY | E16: 4000 | G16: 0.5 | H16: Urvan | I16: 5560318920 | J16: =IF(AND(ISNUMBER(E16), ISNUMBER(G16)), E16*(1-G16), 0) -> 2000 | K16: =IF(AND(ISNUMBER(E16), ISNUMBER(G16)), E16*G16, 0) -> 2000
B17: 25 | C17: PIERCING | D17: VONY | E17: 100 | G17: 0.5 | J17: =IF(AND(ISNUMBER(E17), ISNUMBER(G17)), E17*(1-G17), 0) -> 50 | K17: =IF(AND(ISNUMBER(E17), ISNUMBER(G17)), E17*G17, 0) -> 50
B18: 27 | C18: TATTOO | D18: VONY | E18: 3200 | G18: 0.5 | H18: Edgar Santana | I18: 3329045164 | J18: =IF(AND(ISNUMBER(E18), ISNUMBER(G18)), E18*(1-G18), 0) -> 1600 | K18: =IF(AND(ISNUMBER(E18), ISNUMBER(G18)), E18*G18, 0) -> 1600
B19: 29 | C19: TATTOO | D19: VONY | E19: 1800 | G19: 0.5 | H19: Adalid | I19: 5559076452 | J19: =IF(AND(ISNUMBER(E19), ISNUMBER(G19)), E19*(1-G19), 0) -> 900 | K19: =IF(AND(ISNUMBER(E19), ISNUMBER(G19)), E19*G19, 0) -> 900
B20: 31 | C20: TATTOO | D20: VONY | E20: 2500 | G20: 0.5 | H20: Jesus Garcia | I20: 3173877438 | J20: =IF(AND(ISNUMBER(E20), ISNUMBER(G20)), E20*(1-G20), 0) -> 1250 | K20: =IF(AND(ISNUMBER(E20), ISNUMBER(G20)), E20*G20, 0) -> 1250
